Workbook

Sheet DASHBOARD GERAL
B2: DASHBOARD — MANIFESTO ELETRÔNICO SANTRI | Q2: GRÁFICOS DASHBOARD — MANIFESTO ELETRÔNICO SANTRI
B4: Visão executiva + operacional: lojas, motoristas, evidências, assinatura do motorista e baixa.
B5: Taxa de Conformidade do Processo de Entrega (OK) | D5: Índice de Saúde Operacional | F5: % Assinatura Motorista | H5: % Evidência | J5: % Baixado | L5: Taxa de Conformidade do Processo de Entrega (% NOK) | N5: Total Auditado
B6: =IFERROR(COUNTIF(TRATAMENTO!K:K,"OK")/(COUNTIF(TRATAMENTO!K:K,"OK")+COUNTIF(TRATAMENTO!K:K,"NOK")),0) -> 0.54716981 | D6: =IFERROR(AVERAGEIF(TRATAMENTO!V:V,">0"),0) -> 0.77538462 | F6: =IFERROR(COUNTIF(CONTROLE_DIARIO!F:F,"SIM")/(COUNTIF(CONTROLE_DIARIO!F:F,"SIM")+COUNTIF(CONTROLE_DIARIO!F:F,"NÃO")),0) -> 0.69230769 | H6: =IFERROR(COUNTIF(CONTROLE_DIARIO!J:J,"SIM")/(COUNTIF(CONTROLE_DIARIO!J:J,"SIM")+COUNTIF(CONTROLE_DIARIO!J:J,"NÃO")),0) -> 0.6 | J6: =IFERROR(COUNTIF(CONTROLE_DIARIO!I:I,"SIM")/(COUNTIF(CONTROLE_DIARIO!I:I,"SIM")+COUNTIF(CONTROLE_DIARIO!I:I,"NÃO")),0) -> 1 | L6: =IFERROR(COUNTIF(TRATAMENTO!K:K,"NOK")/(COUNTIF(TRATAMENTO!K:K,"OK")+COUNTIF(TRATAMENTO!K:K,"NOK")),0) -> 0.45283019 | N6: =COUNTA(CONTROLE_DIARIO!C:C)-1 -> 159
B9: Meta: ≥95% OK | Atenção: 85% a 94,9% | Crítico: abaixo de 85%
B11: RANKING POR LOJA | H11: RANKING POR MOTORISTA | N11: STATUS SANTRI
B12: Loja | C12: Auditorias | D12: OK | E12: NOK | F12: TCPE | H12: Motorista | I12: Auditorias | J12: OK | K12: NOK | L12: TCPE | N12: Status | O12: Qtde
B13: =AUXILIAR!C2 -> Loja Pistão | C13: =COUNTIF(TRATAMENTO!B:B,B13) -> 44 | D13: =COUNTIFS(TRATAMENTO!B:B,B13,TRATAMENTO!K:K,"OK") -> 31 | E13: =COUNTIFS(TRATAMENTO!B:B,B13,TRATAMENTO!K:K,"NOK") -> 13 | F13: =IFERROR(D13/C13,0) -> 0.70454545 | H13: =AUXILIAR!E2 -> João Lucas | I13: =COUNTIF(TRATAMENTO!D:D,H13) -> 82 | J13: =COUNTIFS(TRATAMENTO!D:D,H13,TRATAMENTO!K:K,"OK") -> 56 | K13: =COUNTIFS(TRATAMENTO!D:D,H13,TRATAMENTO!K:K,"NOK") -> 26 | L13: =IFERROR(J13/I13,0) -> 0.68292683 | N13: =AUXILIAR!G2 -> Entrega Total | O13: =COUNTIF(CONTROLE_DIARIO!E:E,N13) -> 130
B14: =AUXILIAR!C3 -> Loja Asa Norte | C14: =COUNTIF(TRATAMENTO!B:B,B14) -> 33 | D14: =COUNTIFS(TRATAMENTO!B:B,B14,TRATAMENTO!K:K,"OK") -> 0 | E14: =COUNTIFS(TRATAMENTO!B:B,B14,TRATAMENTO!K:K,"NOK") -> 33 | F14: =IFERROR(D14/C14,0) -> 0 | H14: =AUXILIAR!E3 -> Jusley | I14: =COUNTIF(TRATAMENTO!D:D,H14) -> 3 | J14: =COUNTIFS(TRATAMENTO!D:D,H14,TRATAMENTO!K:K,"OK") -> 0 | K14: =COUNTIFS(TRATAMENTO!D:D,H14,TRATAMENTO!K:K,"NOK") -> 3 | L14: =IFERROR(J14/I14,0) -> 0 | N14: =AUXILIAR!G3 -> Retorno Total | O14: =COUNTIF(CONTROLE_DIARIO!E:E,N14) -> 1
B15: =AUXILIAR!C4 -> Loja Aguas Lindas | C15: =COUNTIF(TRATAMENTO!B:B,B15) -> 3 | D15: =COUNTIFS(TRATAMENTO!B:B,B15,TRATAMENTO!K:K,"OK") -> 0 | E15: =COUNTIFS(TRATAMENTO!B:B,B15,TRATAMENTO!K:K,"NOK") -> 3 | F15: =IFERROR(D15/C15,0) -> 0 | H15: =AUXILIAR!E4 -> J. Alessandro | I15: =COUNTIF(TRATAMENTO!D:D,H15) -> 34 | J15: =COUNTIFS(TRATAMENTO!D:D,H15,TRATAMENTO!K:K,"OK") -> 0 | K15: =COUNTIFS(TRATAMENTO!D:D,H15,TRATAMENTO!K:K,"NOK") -> 34 | L15: =IFERROR(J15/I15,0) -> 0 | N15: =AUXILIAR!G4 -> Entrega Parcial | O15: =COUNTIF(CONTROLE_DIARIO!E:E,N15) -> 0
B16: =AUXILIAR!C5 -> Loja Valparaiso | C16: =COUNTIF(TRATAMENTO!B:B,B16) -> 41 | D16: =COUNTIFS(TRATAMENTO!B:B,B16,TRATAMENTO!K:K,"OK") -> 31 | E16: =COUNTIFS(TRATAMENTO!B:B,B16,TRATAMENTO!K:K,"NOK") -> 10 | F16: =IFERROR(D16/C16,0) -> 0.75609756 | H16: =AUXILIAR!E5 -> Wederson C. | I16: =COUNTIF(TRATAMENTO!D:D,H16) -> 40 | J16: =COUNTIFS(TRATAMENTO!D:D,H16,TRATAMENTO!K:K,"OK") -> 31 | K16: =COUNTIFS(TRATAMENTO!D:D,H16,TRATAMENTO!K:K,"NOK") -> 9 | L16: =IFERROR(J16/I16,0) -> 0.775 | N16: =AUXILIAR!G5 -> Aberto | O16: =COUNTIF(CONTROLE_DIARIO!E:E,N16) -> 15
B17: =AUXILIAR!C6 -> Loja Ceilândia | C17: =COUNTIF(TRATAMENTO!B:B,B17) -> 0 | D17: =COUNTIFS(TRATAMENTO!B:B,B17,TRATAMENTO!K:K,"OK") -> 0 | E17: =COUNTIFS(TRATAMENTO!B:B,B17,TRATAMENTO!K:K,"NOK") -> 0 | F17: =IFERROR(D17/C17,0) -> 0 | H17: =AUXILIAR!E6 -> 0 | I17: =COUNTIF(TRATAMENTO!D:D,H17) -> 337 | J17: =COUNTIFS(TRATAMENTO!D:D,H17,TRATAMENTO!K:K,"OK") -> 0 | K17: =COUNTIFS(TRATAMENTO!D:D,H17,TRATAMENTO!K:K,"NOK") -> 0 | L17: =IFERROR(J17/I17,0) -> 0 | N17: =AUXILIAR!G6 -> Devolução Avaria | O17: =COUNTIF(CONTROLE_DIARIO!E:E,N17) -> 0
B18: =AUXILIAR!C7 -> Loja ADE | C18: =COUNTIF(TRATAMENTO!B:B,B18) -> 38 | D18: =COUNTIFS(TRATAMENTO!B:B,B18,TRATAMENTO!K:K,"OK") -> 25 | E18: =COUNTIFS(TRATAMENTO!B:B,B18,TRATAMENTO!K:K,"NOK") -> 13 | F18: =IFERROR(D18/C18,0) -> 0.65789474 | H18: =AUXILIAR!E7 -> 0 | I18: =COUNTIF(TRATAMENTO!D:D,H18) -> 337 | J18: =COUNTIFS(TRATAMENTO!D:D,H18,TRATAMENTO!K:K,"OK") -> 0 | K18: =COUNTIFS(TRATAMENTO!D:D,H18,TRATAMENTO!K:K,"NOK") -> 0 | L18: =IFERROR(J18/I18,0) -> 0 | N18: =AUXILIAR!G7 -> Cancelado | O18: =COUNTIF(CONTROLE_DIARIO!E:E,N18) -> 13
B19: =AUXILIAR!C8 -> Loja Matriz | C19: =COUNTIF(TRATAMENTO!B:B,B19) -> 0 | D19: =COUNTIFS(TRATAMENTO!B:B,B19,TRATAMENTO!K:K,"OK") -> 0 | E19: =COUNTIFS(TRATAMENTO!B:B,B19,TRATAMENTO!K:K,"NOK") -> 0 | F19: =IFERROR(D19/C19,0) -> 0 | H19: =AUXILIAR!E8 -> 0 | I19: =COUNTIF(TRATAMENTO!D:D,H19) -> 337 | J19: =COUNTIFS(TRATAMENTO!D:D,H19,TRATAMENTO!K:K,"OK") -> 0 | K19: =COUNTIFS(TRATAMENTO!D:D,H19,TRATAMENTO!K:K,"NOK") -> 0 | L19: =IFERROR(J19/I19,0) -> 0
B20: =AUXILIAR!C9 -> Loja Luziânia | C20: =COUNTIF(TRATAMENTO!B:B,B20) -> 0 | D20: =COUNTIFS(TRATAMENTO!B:B,B20,TRATAMENTO!K:K,"OK") -> 0 | E20: =COUNTIFS(TRATAMENTO!B:B,B20,TRATAMENTO!K:K,"NOK") -> 0 | F20: =IFERROR(D20/C20,0) -> 0 | H20: =AUXILIAR!E9 -> 0 | I20: =COUNTIF(TRATAMENTO!D:D,H20) -> 337 | J20: =COUNTIFS(TRATAMENTO!D:D,H20,TRATAMENTO!K:K,"OK") -> 0 | K20: =COUNTIFS(TRATAMENTO!D:D,H20,TRATAMENTO!K:K,"NOK") -> 0 | L20: =IFERROR(J20/I20,0) -> 0
B22: EVOLUÇÃO MENSAL | H22: FALHAS IDENTIFICADAS | L22: PEDIDOS 100% OK (SEM NENHUMA FALHA)
B23: Mês | C23: Total | D23: OK | E23: NOK | F23: TCPE | H23: Erro | I23: Qtde | J23: % | L23: Status | M23: Qtde | N23: %
B24: 46113 | C24: =COUNTIFS(TRATAMENTO!A:A,">="&B24,TRATAMENTO!A:A,"<"&EDATE(B24,1)) -> 8 | D24: =COUNTIFS(TRATAMENTO!A:A,">="&B24,TRATAMENTO!A:A,"<"&EDATE(B24,1),TRATAMENTO!K:K,"OK") -> 6 | E24: =COUNTIFS(TRATAMENTO!A:A,">="&B24,TRATAMENTO!A:A,"<"&EDATE(B24,1),TRATAMENTO!K:K,"NOK") -> 2 | F24: =IFERROR(D24/C24,0) -> 0.75 | H24: =AUXILIAR!I3 -> Sem assinatura | I24: =COUNTIF(TRATAMENTO!R:R,H24) -> 2 | J24: =IFERROR(I24/SUM($I$24:$I$32),0) -> 0.019417476 | L24: OK | M24: =COUNTIF(CONTROLE_DIARIO!L:L,"OK") -> 40 | N24: =IFERROR(COUNTIF(CONTROLE_DIARIO!L:L,"OK")/(COUNTA(CONTROLE_DIARIO!L:L)-1),0) -> 0.27777778
B25: 46143 | C25: =COUNTIFS(TRATAMENTO!A:A,">="&B25,TRATAMENTO!A:A,"<"&EDATE(B25,1)) -> 151 | D25: =COUNTIFS(TRATAMENTO!A:A,">="&B25,TRATAMENTO!A:A,"<"&EDATE(B25,1),TRATAMENTO!K:K,"OK") -> 81 | E25: =COUNTIFS(TRATAMENTO!A:A,">="&B25,TRATAMENTO!A:A,"<"&EDATE(B25,1),TRATAMENTO!K:K,"NOK") -> 70 | F25: =IFERROR(D25/C25,0) -> 0.53642384 | H25: =AUXILIAR!I4 -> Sem nenhuma foto | I25: =COUNTIF(TRATAMENTO!L:L,H25) -> 1 | J25: =IFERROR(I25/SUM($I$24:$I$32),0) -> 0.0097087379 | L25: NOK | M25: =COUNTA(CONTROLE_DIARIO!L:L)-COUNTIF(CONTROLE_DIARIO!L:L,"OK")-1 -> 104 | N25: =IFERROR((COUNTA(CONTROLE_DIARIO!L:L)-COUNTIF(CONTROLE_DIARIO!L:L,"OK")-1)/(COUNTA(CONTROLE_DIARIO!L:L)-1),0) -> 0.72222222
B26: 46174 | C26: =COUNTIFS(TRATAMENTO!A:A,">="&B26,TRATAMENTO!A:A,"<"&EDATE(B26,1)) -> 0 | D26: =COUNTIFS(TRATAMENTO!A:A,">="&B26,TRATAMENTO!A:A,"<"&EDATE(B26,1),TRATAMENTO!K:K,"OK") -> 0 | E26: =COUNTIFS(TRATAMENTO!A:A,">="&B26,TRATAMENTO!A:A,"<"&EDATE(B26,1),TRATAMENTO!K:K,"NOK") -> 0 | F26: =IFERROR(D26/C26,0) -> 0 | H26: =AUXILIAR!I5 -> Sem foto fachada | I26: =COUNTIF(TRATAMENTO!L:L,H26) -> 47 | J26: =IFERROR(I26/SUM($I$24:$I$32),0) -> 0.45631068
B27: 46204 | C27: =COUNTIFS(TRATAMENTO!A:A,">="&B27,TRATAMENTO!A:A,"<"&EDATE(B27,1)) -> 0 | D27: =COUNTIFS(TRATAMENTO!A:A,">="&B27,TRATAMENTO!A:A,"<"&EDATE(B27,1),TRATAMENTO!K:K,"OK") -> 0 | E27: =COUNTIFS(TRATAMENTO!A:A,">="&B27,TRATAMENTO!A:A,"<"&EDATE(B27,1),TRATAMENTO!K:K,"NOK") -> 0 | F27: =IFERROR(D27/C27,0) -> 0 | H27: =AUXILIAR!I6 -> Sem foto produtos | I27: =COUNTIF(TRATAMENTO!L:L,H27) -> 0 | J27: =IFERROR(I27/SUM($I$24:$I$32),0) -> 0
B28: 46235 | C28: =COUNTIFS(TRATAMENTO!A:A,">="&B28,TRATAMENTO!A:A,"<"&EDATE(B28,1)) -> 0 | D28: =COUNTIFS(TRATAMENTO!A:A,">="&B28,TRATAMENTO!A:A,"<"&EDATE(B28,1),TRATAMENTO!K:K,"OK") -> 0 | E28: =COUNTIFS(TRATAMENTO!A:A,">="&B28,TRATAMENTO!A:A,"<"&EDATE(B28,1),TRATAMENTO!K:K,"NOK") -> 0 | F28: =IFERROR(D28/C28,0) -> 0 | H28: =AUXILIAR!I7 -> Sem fotos e assinatura | I28: =COUNTIF(TRATAMENTO!R:R,H28) -> 0 | J28: =IFERROR(I28/SUM($I$24:$I$32),0) -> 0
B29: 46266 | C29: =COUNTIFS(TRATAMENTO!A:A,">="&B29,TRATAMENTO!A:A,"<"&EDATE(B29,1)) -> 0 | D29: =COUNTIFS(TRATAMENTO!A:A,">="&B29,TRATAMENTO!A:A,"<"&EDATE(B29,1),TRATAMENTO!K:K,"OK") -> 0 | E29: =COUNTIFS(TRATAMENTO!A:A,">="&B29,TRATAMENTO!A:A,"<"&EDATE(B29,1),TRATAMENTO!K:K,"NOK") -> 0 | F29: =IFERROR(D29/C29,0) -> 0 | H29: =AUXILIAR!I8 -> Não conferido | I29: =COUNTIF(TRATAMENTO!R:R,H29) -> 0 | J29: =IFERROR(I29/SUM($I$24:$I$32),0) -> 0 | R29: Legenda:
B30: 46296 | C30: =COUNTIFS(TRATAMENTO!A:A,">="&B30,TRATAMENTO!A:A,"<"&EDATE(B30,1)) -> 0 | D30: =COUNTIFS(TRATAMENTO!A:A,">="&B30,TRATAMENTO!A:A,"<"&EDATE(B30,1),TRATAMENTO!K:K,"OK") -> 0 | E30: =COUNTIFS(TRATAMENTO!A:A,">="&B30,TRATAMENTO!A:A,"<"&EDATE(B30,1),TRATAMENTO!K:K,"NOK") -> 0 | F30: =IFERROR(D30/C30,0) -> 0 | H30: =AUXILIAR!I9 -> Não baixado | I30: =COUNTIF(TRATAMENTO!R:R,H30) -> 0 | J30: =IFERROR(I30/SUM($I$24:$I$32),0) -> 0 | R30: *TCPE = Taxa de Conformidade do Processo de Entrega
B31: 46327 | C31: =COUNTIFS(TRATAMENTO!A:A,">="&B31,TRATAMENTO!A:A,"<"&EDATE(B31,1)) -> 0 | D31: =COUNTIFS(TRATAMENTO!A:A,">="&B31,TRATAMENTO!A:A,"<"&EDATE(B31,1),TRATAMENTO!K:K,"OK") -> 0 | E31: =COUNTIFS(TRATAMENTO!A:A,">="&B31,TRATAMENTO!A:A,"<"&EDATE(B31,1),TRATAMENTO!K:K,"NOK") -> 0 | F31: =IFERROR(D31/C31,0) -> 0 | H31: Fora APP | I31: =COUNTIF(TRATAMENTO!R:R,H31) -> 40 | J31: =IFERROR(I31/SUM($I$24:$I$32),0) -> 0.38834951
B32: 46357 | C32: =COUNTIFS(TRATAMENTO!A:A,">="&B32,TRATAMENTO!A:A,"<"&EDATE(B32,1)) -> 0 | D32: =COUNTIFS(TRATAMENTO!A:A,">="&B32,TRATAMENTO!A:A,"<"&EDATE(B32,1),TRATAMENTO!K:K,"OK") -> 0 | E32: =COUNTIFS(TRATAMENTO!A:A,">="&B32,TRATAMENTO!A:A,"<"&EDATE(B32,1),TRATAMENTO!K:K,"NOK") -> 0 | F32: =IFERROR(D32/C32,0) -> 0 | H32: =AUXILIAR!I10 -> Manifesto cancelado | I32: =COUNTIF(TRATAMENTO!R:R,H32) -> 13 | J32: =IFERROR(I32/SUM($I$24:$I$32),0) -> 0.12621359
H33: =AUXILIAR!I11 -> Outro | I33: =COUNTIF(TRATAMENTO!R:R,H33) -> 0 | J33: =IFERROR(I33/SUM($I$24:$I$32),0) -> 0

Sheet DASHBOARD ADE
B2: DASHBOARD ADE — MANIFESTO ELETRÔNICO SANTRI | Q2: GRÁFICOS DASHBOARD — MANIFESTO ELETRÔNICO SANTRI
B4: Visão executiva + operacional: lojas, motoristas, evidências, assinatura do motorista e baixa.
B5: Taxa de Conformidade do Processo de Entrega (OK) | D5: Índice de Saúde Operacional | F5: % Assinatura Motorista | H5: % Evidência | J5: % Baixado | L5: Taxa de Conformidade do Processo de Entrega (% NOK) | N5: Total Auditado
B6: =IFERROR(COUNTIFS(TRATAMENTO!B:B,"Loja ADE",TRATAMENTO!K:K,"OK")/(COUNTIFS(TRATAMENTO!B:B,"Loja ADE",TRATAMENTO!K:K,"OK")+COUNTIFS(TRATAMENTO!B:B,"Loja ADE",TRATAMENTO!K:K,"NOK")),0) -> 0.65789474 | D6: =IFERROR(SUMIFS(TRATAMENTO!V5:V500,TRATAMENTO!B5:B500,"Loja ADE",TRATAMENTO!V5:V500,">0")/COUNTIFS(TRATAMENTO!B5:B500,"Loja ADE",TRATAMENTO!V5:V500,">0"),0) -> 0.92413793 | F6: =IFERROR(COUNTIFS(CONTROLE_DIARIO!B6:B500,"Loja ADE",CONTROLE_DIARIO!F6:F500,"SIM")/(COUNTIFS(CONTROLE_DIARIO!B6:B500,"Loja ADE",CONTROLE_DIARIO!F6:F500,"SIM")+COUNTIFS(CONTROLE_DIARIO!B6:B500,"Loja ADE",CONTROLE_DIARIO!F6:F500,"NÃO")),0) -> 0.93103448 | H6: =IFERROR(COUNTIFS(CONTROLE_DIARIO!B6:B500,"Loja ADE",CONTROLE_DIARIO!J6:J500,"SIM")/(COUNTIFS(CONTROLE_DIARIO!B6:B500,"Loja ADE",CONTROLE_DIARIO!J6:J500,"SIM")+COUNTIFS(CONTROLE_DIARIO!B6:B500,"Loja ADE",CONTROLE_DIARIO!J6:J500,"NÃO")),0) -> 0.69444444 | J6: =IFERROR(COUNTIFS(CONTROLE_DIARIO!B6:B500,"Loja ADE",CONTROLE_DIARIO!I6:I500,"SIM")/(COUNTIFS(CONTROLE_DIARIO!B6:B500,"Loja ADE",CONTROLE_DIARIO!I6:I500,"SIM")+COUNTIFS(CONTROLE_DIARIO!B6:B500,"Loja ADE",CONTROLE_DIARIO!I6:I500,"NÃO")),0) -> 1 | L6: =IFERROR(COUNTIFS(TRATAMENTO!B:B,"Loja ADE",TRATAMENTO!K:K,"NOK")/(COUNTIFS(TRATAMENTO!B:B,"Loja ADE",TRATAMENTO!K:K,"OK")+COUNTIFS(TRATAMENTO!B:B,"Loja ADE",TRATAMENTO!K:K,"NOK")),0) -> 0.34210526 | M6: 0 | N6: =COUNTIF(CONTROLE_DIARIO!B:B,"Loja ADE") -> 38
L7: 0.20689655 | M7: 0
B9: Meta: ≥95% OK | Atenção: 85% a 94,9% | Crítico: abaixo de 85%
B11: EVOLUÇÃO MENSAL | H11: FALHAS IDENTIFICADAS | L11: PEDIDOS 100% OK (SEM NENHUMA FALHA)
B12: Mês | C12: Total | D12: OK | E12: NOK | F12: TCPE | H12: Erro | I12: Qtde | J12: % | L12: Status | M12: Qtde | N12: %
B13: 46113 | C13: =COUNTIFS(TRATAMENTO!B:B,"Loja ADE",TRATAMENTO!A:A,">="&B13,TRATAMENTO!A:A,"<"&EDATE(B13,1)) -> 8 | D13: =COUNTIFS(TRATAMENTO!B:B,"Loja ADE",TRATAMENTO!A:A,">="&B13,TRATAMENTO!A:A,"<"&EDATE(B13,1),TRATAMENTO!K:K,"OK") -> 6 | E13: =COUNTIFS(TRATAMENTO!B:B,"Loja ADE",TRATAMENTO!A:A,">="&B13,TRATAMENTO!A:A,"<"&EDATE(B13,1),TRATAMENTO!K:K,"NOK") -> 2 | F13: =IFERROR(D13/C13,0) -> 0.75 | H13: =AUXILIAR!I3 -> Sem assinatura | I13: =COUNTIFS(TRATAMENTO!B:B,"Loja ADE",TRATAMENTO!R:R,H13) -> 2 | J13: =IFERROR(I13/SUM($I$13:$I$22),0) -> 0.2 | L13: OK | M13: =COUNTIFS(TRATAMENTO!B:B,"Loja ADE",TRATAMENTO!K:K,"OK") -> 25 | N13: =IFERROR(M13/(M13+M14),0) -> 0.65789474
B14: 46143 | C14: =COUNTIFS(TRATAMENTO!B:B,"Loja ADE",TRATAMENTO!A:A,">="&B14,TRATAMENTO!A:A,"<"&EDATE(B14,1)) -> 30 | D14: =COUNTIFS(TRATAMENTO!B:B,"Loja ADE",TRATAMENTO!A:A,">="&B14,TRATAMENTO!A:A,"<"&EDATE(B14,1),TRATAMENTO!K:K,"OK") -> 19 | E14: =COUNTIFS(TRATAMENTO!B:B,"Loja ADE",TRATAMENTO!A:A,">="&B14,TRATAMENTO!A:A,"<"&EDATE(B14,1),TRATAMENTO!K:K,"NOK") -> 11 | F14: =IFERROR(D14/C14,0) -> 0.63333333 | H14: =AUXILIAR!I4 -> Sem nenhuma foto | I14: =COUNTIFS(TRATAMENTO!B:B,"Loja ADE",TRATAMENTO!L:L,H14) -> 0 | J14: =IFERROR(I14/SUM($I$13:$I$22),0) -> 0 | L14: NOK | M14: =COUNTIFS(TRATAMENTO!B:B,"Loja ADE",TRATAMENTO!K:K,"NOK") -> 13 | N14: =IFERROR(M14/(M13+M14),0) -> 0.34210526
B15: 46174 | C15: =COUNTIFS(TRATAMENTO!B:B,"Loja ADE",TRATAMENTO!A:A,">="&B15,TRATAMENTO!A:A,"<"&EDATE(B15,1)) -> 0 | D15: =COUNTIFS(TRATAMENTO!B:B,"Loja ADE",TRATAMENTO!A:A,">="&B15,TRATAMENTO!A:A,"<"&EDATE(B15,1),TRATAMENTO!K:K,"OK") -> 0 | E15: =COUNTIFS(TRATAMENTO!B:B,"Loja ADE",TRATAMENTO!A:A,">="&B15,TRATAMENTO!A:A,"<"&EDATE(B15,1),TRATAMENTO!K:K,"NOK") -> 0 | F15: =IFERROR(D15/C15,0) -> 0 | H15: =AUXILIAR!I5 -> Sem foto fachada | I15: =COUNTIFS(TRATAMENTO!B:B,"Loja ADE",TRATAMENTO!L:L,H15) -> 5 | J15: =IFERROR(I15/SUM($I$13:$I$22),0) -> 0.5
B16: 46204 | C16: =COUNTIFS(TRATAMENTO!B:B,"Loja ADE",TRATAMENTO!A:A,">="&B16,TRATAMENTO!A:A,"<"&EDATE(B16,1)) -> 0 | D16: =COUNTIFS(TRATAMENTO!B:B,"Loja ADE",TRATAMENTO!A:A,">="&B16,TRATAMENTO!A:A,"<"&EDATE(B16,1),TRATAMENTO!K:K,"OK") -> 0 | E16: =COUNTIFS(TRATAMENTO!B:B,"Loja ADE",TRATAMENTO!A:A,">="&B16,TRATAMENTO!A:A,"<"&EDATE(B16,1),TRATAMENTO!K:K,"NOK") -> 0 | F16: =IFERROR(D16/C16,0) -> 0 | H16: =AUXILIAR!I6 -> Sem foto produtos | I16: =COUNTIFS(TRATAMENTO!B:B,"Loja ADE",TRATAMENTO!L:L,H16) -> 0 | J16: =IFERROR(I16/SUM($I$13:$I$22),0) -> 0 | L16: STATUS SANTRI
B17: 46235 | C17: =COUNTIFS(TRATAMENTO!B:B,"Loja ADE",TRATAMENTO!A:A,">="&B17,TRATAMENTO!A:A,"<"&EDATE(B17,1)) -> 0 | D17: =COUNTIFS(TRATAMENTO!B:B,"Loja ADE",TRATAMENTO!A:A,">="&B17,TRATAMENTO!A:A,"<"&EDATE(B17,1),TRATAMENTO!K:K,"OK") -> 0 | E17: =COUNTIFS(TRATAMENTO!B:B,"Loja ADE",TRATAMENTO!A:A,">="&B17,TRATAMENTO!A:A,"<"&EDATE(B17,1),TRATAMENTO!K:K,"NOK") -> 0 | F17: =IFERROR(D17/C17,0) -> 0 | H17: =AUXILIAR!I7 -> Sem fotos e assinatura | I17: =COUNTIFS(TRATAMENTO!B:B,"Loja ADE",TRATAMENTO!R:R,H17) -> 0 | J17: =IFERROR(I17/SUM($I$13:$I$22),0) -> 0 | L17: Status | M17: Qtde
B18: 46266 | C18: =COUNTIFS(TRATAMENTO!B:B,"Loja ADE",TRATAMENTO!A:A,">="&B18,TRATAMENTO!A:A,"<"&EDATE(B18,1)) -> 0 | D18: =COUNTIFS(TRATAMENTO!B:B,"Loja ADE",TRATAMENTO!A:A,">="&B18,TRATAMENTO!A:A,"<"&EDATE(B18,1),TRATAMENTO!K:K,"OK") -> 0 | E18: =COUNTIFS(TRATAMENTO!B:B,"Loja ADE",TRATAMENTO!A:A,">="&B18,TRATAMENTO!A:A,"<"&EDATE(B18,1),TRATAMENTO!K:K,"NOK") -> 0 | F18: =IFERROR(D18/C18,0) -> 0 | H18: =AUXILIAR!I8 -> Não conferido | I18: =COUNTIFS(TRATAMENTO!B:B,"Loja ADE",TRATAMENTO!R:R,H18) -> 0 | J18: =IFERROR(I18/SUM($I$13:$I$22),0) -> 0 | L18: =AUXILIAR!G2 -> Entrega Total | M18: =COUNTIFS(CONTROLE_DIARIO!B:B,"Loja ADE",CONTROLE_DIARIO!E:E,L18) -> 29
B19: 46296 | C19: =COUNTIFS(TRATAMENTO!B:B,"Loja ADE",TRATAMENTO!A:A,">="&B19,TRATAMENTO!A:A,"<"&EDATE(B19,1)) -> 0 | D19: =COUNTIFS(TRATAMENTO!B:B,"Loja ADE",TRATAMENTO!A:A,">="&B19,TRATAMENTO!A:A,"<"&EDATE(B19,1),TRATAMENTO!K:K,"OK") -> 0 | E19: =COUNTIFS(TRATAMENTO!B:B,"Loja ADE",TRATAMENTO!A:A,">="&B19,TRATAMENTO!A:A,"<"&EDATE(B19,1),TRATAMENTO!K:K,"NOK") -> 0 | F19: =IFERROR(D19/C19,0) -> 0 | H19: =AUXILIAR!I9 -> Não baixado | I19: =COUNTIFS(TRATAMENTO!B:B,"Loja ADE",TRATAMENTO!R:R,H19) -> 0 | J19: =IFERROR(I19/SUM($I$13:$I$22),0) -> 0 | L19: =AUXILIAR!G3 -> Retorno Total | M19: =COUNTIFS(CONTROLE_DIARIO!B:B,"Loja ADE",CONTROLE_DIARIO!E:E,L19) -> 1
B20: 46327 | C20: =COUNTIFS(TRATAMENTO!B:B,"Loja ADE",TRATAMENTO!A:A,">="&B20,TRATAMENTO!A:A,"<"&EDATE(B20,1)) -> 0 | D20: =COUNTIFS(TRATAMENTO!B:B,"Loja ADE",TRATAMENTO!A:A,">="&B20,TRATAMENTO!A:A,"<"&EDATE(B20,1),TRATAMENTO!K:K,"OK") -> 0 | E20: =COUNTIFS(TRATAMENTO!B:B,"Loja ADE",TRATAMENTO!A:A,">="&B20,TRATAMENTO!A:A,"<"&EDATE(B20,1),TRATAMENTO!K:K,"NOK") -> 0 | F20: =IFERROR(D20/C20,0) -> 0 | H20: Fora APP | I20: =COUNTIFS(TRATAMENTO!B:B,"Loja ADE",TRATAMENTO!R:R,H20) -> 2 | J20: =IFERROR(I20/SUM($I$13:$I$22),0) -> 0.2 | L20: =AUXILIAR!G4 -> Entrega Parcial | M20: =COUNTIFS(CONTROLE_DIARIO!B:B,"Loja ADE",CONTROLE_DIARIO!E:E,L20) -> 0
B21: 46357 | C21: =COUNTIFS(TRATAMENTO!B:B,"Loja ADE",TRATAMENTO!A:A,">="&B21,TRATAMENTO!A:A,"<"&EDATE(B21,1)) -> 0 | D21: =COUNTIFS(TRATAMENTO!B:B,"Loja ADE",TRATAMENTO!A:A,">="&B21,TRATAMENTO!A:A,"<"&EDATE(B21,1),TRATAMENTO!K:K,"OK") -> 0 | E21: =COUNTIFS(TRATAMENTO!B:B,"Loja ADE",TRATAMENTO!A:A,">="&B21,TRATAMENTO!A:A,"<"&EDATE(B21,1),TRATAMENTO!K:K,"NOK") -> 0 | F21: =IFERROR(D21/C21,0) -> 0 | H21: =AUXILIAR!I10 -> Manifesto cancelado | I21: =COUNTIFS(TRATAMENTO!B:B,"Loja ADE",TRATAMENTO!R:R,H21) -> 1 | J21: =IFERROR(I21/SUM($I$13:$I$22),0) -> 0.1 | L21: =AUXILIAR!G5 -> Aberto | M21: =COUNTIFS(CONTROLE_DIARIO!B:B,"Loja ADE",CONTROLE_DIARIO!E:E,L21) -> 7
H22: =AUXILIAR!I11 -> Outro | I22: =COUNTIFS(TRATAMENTO!B:B,"Loja ADE",TRATAMENTO!R:R,H22) -> 0 | J22: =IFERROR(I22/SUM($I$13:$I$22),0) -> 0 | L22: =AUXILIAR!G6 -> Devolução Avaria | M22: =COUNTIFS(CONTROLE_DIARIO!B:B,"Loja ADE",CONTROLE_DIARIO!E:E,L22) -> 0
B23: RANKING POR MOTORISTA | L23: =AUXILIAR!G7 -> Cancelado | M23: =COUNTIFS(CONTROLE_DIARIO!B:B,"Loja ADE",CONTROLE_DIARIO!E:E,L23) -> 1
B24: Motorista | C24: Auditorias | D24: OK | E24: NOK | F24: TCPE | R24: Legenda:
B25: =AUXILIAR!E2 -> João Lucas | C25: =COUNTIFS(TRATAMENTO!B:B,"Loja ADE",TRATAMENTO!D:D,B25) -> 38 | D25: =COUNTIFS(TRATAMENTO!B:B,"Loja ADE",TRATAMENTO!D:D,B25,TRATAMENTO!K:K,"OK") -> 25 | E25: =COUNTIFS(TRATAMENTO!B:B,"Loja ADE",TRATAMENTO!D:D,B25,TRATAMENTO!K:K,"NOK") -> 13 | F25: =IFERROR(D25/C25,0) -> 0.65789474 | R25: *TCPE = Taxa de Conformidade do Processo de Entrega

Sheet DASHBOARD PIS
B2: DASHBOARD PISTÃO — MANIFESTO ELETRÔNICO SANTRI | Q2: GRÁFICOS DASHBOARD — MANIFESTO ELETRÔNICO SANTRI
B4: Visão executiva + operacional: lojas, motoristas, evidências, assinatura do motorista e baixa.
B5: Taxa de Conformidade do Processo de Entrega (OK) | D5: Índice de Saúde Operacional | F5: % Assinatura Motorista | H5: % Evidência | J5: % Baixado | L5: Taxa de Conformidade do Processo de Entrega (% NOK) | N5: Total Auditado
B6: =IFERROR(COUNTIFS(TRATAMENTO!B:B,"Loja Pistão",TRATAMENTO!K:K,"OK")/(COUNTIFS(TRATAMENTO!B:B,"Loja Pistão",TRATAMENTO!K:K,"OK")+COUNTIFS(TRATAMENTO!B:B,"Loja Pistão",TRATAMENTO!K:K,"NOK")),0) -> 0.70454545 | C6: 0 | D6: =IFERROR(SUMIFS(TRATAMENTO!V5:V500,TRATAMENTO!B5:B500,"Loja Pistão",TRATAMENTO!V5:V500,">0")/COUNTIFS(TRATAMENTO!B5:B500,"Loja Pistão",TRATAMENTO!V5:V500,">0"),0) -> 0.92857143 | E6: 0 | F6: =IFERROR(COUNTIFS(CONTROLE_DIARIO!B6:B500,"Loja Pistão",CONTROLE_DIARIO!F6:F500,"SIM")/(COUNTIFS(CONTROLE_DIARIO!B6:B500,"Loja Pistão",CONTROLE_DIARIO!F6:F500,"SIM")+COUNTIFS(CONTROLE_DIARIO!B6:B500,"Loja Pistão",CONTROLE_DIARIO!F6:F500,"NÃO")),0) -> 0.91428571 | G6: 0 | H6: =IFERROR(COUNTIFS(CONTROLE_DIARIO!B6:B500,"Loja Pistão",CONTROLE_DIARIO!J6:J500,"SIM")/(COUNTIFS(CONTROLE_DIARIO!B6:B500,"Loja Pistão",CONTROLE_DIARIO!J6:J500,"SIM")+COUNTIFS(CONTROLE_DIARIO!B6:B500,"Loja Pistão",CONTROLE_DIARIO!J6:J500,"NÃO")),0) -> 0.72093023 | I6: 0 | J6: =IFERROR(COUNTIFS(CONTROLE_DIARIO!B6:B500,"Loja Pistão",CONTROLE_DIARIO!I6:I500,"SIM")/(COUNTIFS(CONTROLE_DIARIO!B6:B500,"Loja Pistão",CONTROLE_DIARIO!I6:I500,"SIM")+COUNTIFS(CONTROLE_DIARIO!B6:B500,"Loja Pistão",CONTROLE_DIARIO!I6:I500,"NÃO")),0) -> 1 | K6: 0 | L6: 0.11764706 | M6: 0 | N6: =COUNTIF(CONTROLE_DIARIO!B:B,"Loja Pistão") -> 44 | O6: 0
B7: 0.88235294 | C7: 0 | D7: 0.94545455 | E7: 0 | F7: 0.93939394 | G7: 0 | H7: 0.90909091 | I7: 0 | J7: 1 | K7: 0 | L7: 0.20689655 | M7: 0 | N7: 34 | O7: 0
B9: Meta: ≥95% OK | Atenção: 85% a 94,9% | Crítico: abaixo de 85%
B11: EVOLUÇÃO MENSAL | H11: FALHAS IDENTIFICADAS | L11: PEDIDOS 100% OK (SEM NENHUMA FALHA)
B12: Mês | C12: Total | D12: OK | E12: NOK | F12: TCPE | H12: Erro | I12: Qtde | J12: % | L12: Status | M12: Qtde | N12: %
B13: 46113 | C13: =COUNTIFS(TRATAMENTO!B:B,"Loja Pistão",TRATAMENTO!A:A,">="&B13,TRATAMENTO!A:A,"<"&EDATE(B13,1)) -> 0 | D13: =COUNTIFS(TRATAMENTO!B:B,"Loja Pistão",TRATAMENTO!A:A,">="&B13,TRATAMENTO!A:A,"<"&EDATE(B13,1),TRATAMENTO!K:K,"OK") -> 0 | E13: =COUNTIFS(TRATAMENTO!B:B,"Loja Pistão",TRATAMENTO!A:A,">="&B13,TRATAMENTO!A:A,"<"&EDATE(B13,1),TRATAMENTO!K:K,"NOK") -> 0 | F13: =IFERROR(D13/C13,0) -> 0 | H13: =AUXILIAR!I3 -> Sem assinatura | I13: =COUNTIFS(TRATAMENTO!B:B,"Loja Pistão",TRATAMENTO!R:R,H13) -> 0 | J13: =IFERROR(I13/SUM($I$13:$I$22),0) -> 0 | L13: OK | M13: =COUNTIFS(TRATAMENTO!B:B,"Loja Pistão",TRATAMENTO!K:K,"OK") -> 31 | N13: =IFERROR(M13/(M13+M14),0) -> 0.70454545
B14: 46143 | C14: =COUNTIFS(TRATAMENTO!B:B,"Loja Pistão",TRATAMENTO!A:A,">="&B14,TRATAMENTO!A:A,"<"&EDATE(B14,1)) -> 44 | D14: =COUNTIFS(TRATAMENTO!B:B,"Loja Pistão",TRATAMENTO!A:A,">="&B14,TRATAMENTO!A:A,"<"&EDATE(B14,1),TRATAMENTO!K:K,"OK") -> 31 | E14: =COUNTIFS(TRATAMENTO!B:B,"Loja Pistão",TRATAMENTO!A:A,">="&B14,TRATAMENTO!A:A,"<"&EDATE(B14,1),TRATAMENTO!K:K,"NOK") -> 13 | F14: =IFERROR(D14/C14,0) -> 0.70454545 | H14: =AUXILIAR!I4 -> Sem nenhuma foto | I14: =COUNTIFS(TRATAMENTO!B:B,"Loja Pistão",TRATAMENTO!L:L,H14) -> 1 | J14: =IFERROR(I14/SUM($I$13:$I$22),0) -> 0.0625 | L14: NOK | M14: =COUNTIFS(TRATAMENTO!B:B,"Loja Pistão",TRATAMENTO!K:K,"NOK") -> 13 | N14: =IFERROR(M14/(M13+M14),0) -> 0.29545455
B15: 46174 | C15: =COUNTIFS(TRATAMENTO!B:B,"Loja Pistão",TRATAMENTO!A:A,">="&B15,TRATAMENTO!A:A,"<"&EDATE(B15,1)) -> 0 | D15: =COUNTIFS(TRATAMENTO!B:B,"Loja Pistão",TRATAMENTO!A:A,">="&B15,TRATAMENTO!A:A,"<"&EDATE(B15,1),TRATAMENTO!K:K,"OK") -> 0 | E15: =COUNTIFS(TRATAMENTO!B:B,"Loja Pistão",TRATAMENTO!A:A,">="&B15,TRATAMENTO!A:A,"<"&EDATE(B15,1),TRATAMENTO!K:K,"NOK") -> 0 | F15: =IFERROR(D15/C15,0) -> 0 | H15: =AUXILIAR!I5 -> Sem foto fachada | I15: =COUNTIFS(TRATAMENTO!B:B,"Loja Pistão",TRATAMENTO!L:L,H15) -> 11 | J15: =IFERROR(I15/SUM($I$13:$I$22),0) -> 0.6875
B16: 46204 | C16: =COUNTIFS(TRATAMENTO!B:B,"Loja Pistão",TRATAMENTO!A:A,">="&B16,TRATAMENTO!A:A,"<"&EDATE(B16,1)) -> 0 | D16: =COUNTIFS(TRATAMENTO!B:B,"Loja Pistão",TRATAMENTO!A:A,">="&B16,TRATAMENTO!A:A,"<"&EDATE(B16,1),TRATAMENTO!K:K,"OK") -> 0 | E16: =COUNTIFS(TRATAMENTO!B:B,"Loja Pistão",TRATAMENTO!A:A,">="&B16,TRATAMENTO!A:A,"<"&EDATE(B16,1),TRATAMENTO!K:K,"NOK") -> 0 | F16: =IFERROR(D16/C16,0) -> 0 | H16: =AUXILIAR!I6 -> Sem foto produtos | I16: =COUNTIFS(TRATAMENTO!B:B,"Loja Pistão",TRATAMENTO!L:L,H16) -> 0 | J16: =IFERROR(I16/SUM($I$13:$I$22),0) -> 0 | L16: STATUS SANTRI
B17: 46235 | C17: =COUNTIFS(TRATAMENTO!B:B,"Loja Pistão",TRATAMENTO!A:A,">="&B17,TRATAMENTO!A:A,"<"&EDATE(B17,1)) -> 0 | D17: =COUNTIFS(TRATAMENTO!B:B,"Loja Pistão",TRATAMENTO!A:A,">="&B17,TRATAMENTO!A:A,"<"&EDATE(B17,1),TRATAMENTO!K:K,"OK") -> 0 | E17: =COUNTIFS(TRATAMENTO!B:B,"Loja Pistão",TRATAMENTO!A:A,">="&B17,TRATAMENTO!A:A,"<"&EDATE(B17,1),TRATAMENTO!K:K,"NOK") -> 0 | F17: =IFERROR(D17/C17,0) -> 0 | H17: =AUXILIAR!I7 -> Sem fotos e assinatura | I17: =COUNTIFS(TRATAMENTO!B:B,"Loja Pistão",TRATAMENTO!R:R,H17) -> 0 | J17: =IFERROR(I17/SUM($I$13:$I$22),0) -> 0 | L17: Status | M17: Qtde
B18: 46266 | C18: =COUNTIFS(TRATAMENTO!B:B,"Loja Pistão",TRATAMENTO!A:A,">="&B18,TRATAMENTO!A:A,"<"&EDATE(B18,1)) -> 0 | D18: =COUNTIFS(TRATAMENTO!B:B,"Loja Pistão",TRATAMENTO!A:A,">="&B18,TRATAMENTO!A:A,"<"&EDATE(B18,1),TRATAMENTO!K:K,"OK") -> 0 | E18: =COUNTIFS(TRATAMENTO!B:B,"Loja Pistão",TRATAMENTO!A:A,">="&B18,TRATAMENTO!A:A,"<"&EDATE(B18,1),TRATAMENTO!K:K,"NOK") -> 0 | F18: =IFERROR(D18/C18,0) -> 0 | H18: =AUXILIAR!I8 -> Não conferido | I18: =COUNTIFS(TRATAMENTO!B:B,"Loja Pistão",TRATAMENTO!R:R,H18) -> 0 | J18: =IFERROR(I18/SUM($I$13:$I$22),0) -> 0 | L18: =AUXILIAR!G2 -> Entrega Total | M18: =COUNTIFS(CONTROLE_DIARIO!B:B,"Loja Pistão",CONTROLE_DIARIO!E:E,L18) -> 35
B19: 46296 | C19: =COUNTIFS(TRATAMENTO!B:B,"Loja Pistão",TRATAMENTO!A:A,">="&B19,TRATAMENTO!A:A,"<"&EDATE(B19,1)) -> 0 | D19: =COUNTIFS(TRATAMENTO!B:B,"Loja Pistão",TRATAMENTO!A:A,">="&B19,TRATAMENTO!A:A,"<"&EDATE(B19,1),TRATAMENTO!K:K,"OK") -> 0 | E19: =COUNTIFS(TRATAMENTO!B:B,"Loja Pistão",TRATAMENTO!A:A,">="&B19,TRATAMENTO!A:A,"<"&EDATE(B19,1),TRATAMENTO!K:K,"NOK") -> 0 | F19: =IFERROR(D19/C19,0) -> 0 | H19: =AUXILIAR!I9 -> Não baixado | I19: =COUNTIFS(TRATAMENTO!B:B,"Loja Pistão",TRATAMENTO!R:R,H19) -> 0 | J19: =IFERROR(I19/SUM($I$13:$I$22),0) -> 0 | L19: =AUXILIAR!G3 -> Retorno Total | M19: =COUNTIFS(CONTROLE_DIARIO!B:B,"Loja Pistão",CONTROLE_DIARIO!E:E,L19) -> 0
B20: 46327 | C20: =COUNTIFS(TRATAMENTO!B:B,"Loja Pistão",TRATAMENTO!A:A,">="&B20,TRATAMENTO!A:A,"<"&EDATE(B20,1)) -> 0 | D20: =COUNTIFS(TRATAMENTO!B:B,"Loja Pistão",TRATAMENTO!A:A,">="&B20,TRATAMENTO!A:A,"<"&EDATE(B20,1),TRATAMENTO!K:K,"OK") -> 0 | E20: =COUNTIFS(TRATAMENTO!B:B,"Loja Pistão",TRATAMENTO!A:A,">="&B20,TRATAMENTO!A:A,"<"&EDATE(B20,1),TRATAMENTO!K:K,"NOK") -> 0 | F20: =IFERROR(D20/C20,0) -> 0 | H20: Fora APP | I20: =COUNTIFS(TRATAMENTO!B:B,"Loja Pistão",TRATAMENTO!R:R,H20) -> 3 | J20: =IFERROR(I20/SUM($I$13:$I$22),0) -> 0.1875 | L20: =AUXILIAR!G4 -> Entrega Parcial | M20: =COUNTIFS(CONTROLE_DIARIO!B:B,"Loja Pistão",CONTROLE_DIARIO!E:E,L20) -> 0
B21: 46357 | C21: =COUNTIFS(TRATAMENTO!B:B,"Loja Pistão",TRATAMENTO!A:A,">="&B21,TRATAMENTO!A:A,"<"&EDATE(B21,1)) -> 0 | D21: =COUNTIFS(TRATAMENTO!B:B,"Loja Pistão",TRATAMENTO!A:A,">="&B21,TRATAMENTO!A:A,"<"&EDATE(B21,1),TRATAMENTO!K:K,"OK") -> 0 | E21: =COUNTIFS(TRATAMENTO!B:B,"Loja Pistão",TRATAMENTO!A:A,">="&B21,TRATAMENTO!A:A,"<"&EDATE(B21,1),TRATAMENTO!K:K,"NOK") -> 0 | F21: =IFERROR(D21/C21,0) -> 0 | H21: =AUXILIAR!I10 -> Manifesto cancelado | I21: =COUNTIFS(TRATAMENTO!B:B,"Loja Pistão",TRATAMENTO!R:R,H21) -> 1 | J21: =IFERROR(I21/SUM($I$13:$I$22),0) -> 0.0625 | L21: =AUXILIAR!G5 -> Aberto | M21: =COUNTIFS(CONTROLE_DIARIO!B:B,"Loja Pistão",CONTROLE_DIARIO!E:E,L21) -> 8
H22: =AUXILIAR!I11 -> Outro | I22: =COUNTIFS(TRATAMENTO!B:B,"Loja Pistão",TRATAMENTO!R:R,H22) -> 0 | J22: =IFERROR(I22/SUM($I$13:$I$22),0) -> 0 | L22: =AUXILIAR!G6 -> Devolução Avaria | M22: =COUNTIFS(CONTROLE_DIARIO!B:B,"Loja Pistão",CONTROLE_DIARIO!E:E,L22) -> 0
B23: RANKING POR MOTORISTA | L23: =AUXILIAR!G7 -> Cancelado | M23: =COUNTIFS(CONTROLE_DIARIO!B:B,"Loja Pistão",CONTROLE_DIARIO!E:E,L23) -> 1
B24: Motorista | C24: Auditorias | D24: OK | E24: NOK | F24: TCPE | R24: Legenda:
B25: =AUXILIAR!E2 -> João Lucas | C25: =COUNTIFS(TRATAMENTO!B:B,"Loja Pistão",TRATAMENTO!D:D,B25) -> 44 | D25: =COUNTIFS(TRATAMENTO!B:B,"Loja Pistão",TRATAMENTO!D:D,B25,TRATAMENTO!K:K,"OK") -> 31 | E25: =COUNTIFS(TRATAMENTO!B:B,"Loja Pistão",TRATAMENTO!D:D,B25,TRATAMENTO!K:K,"NOK") -> 13 | F25: =IFERROR(D25/C25,0) -> 0.70454545 | R25: *TCPE = Taxa de Conformidade do Processo de Entrega

Sheet DASHBOARD ASA
B2: DASHBOARD ASA NORTE — MANIFESTO ELETRÔNICO SANTRI | Q2: GRÁFICOS DASHBOARD — MANIFESTO ELETRÔNICO SANTRI
B4: Visão executiva + operacional: lojas, motoristas, evidências, assinatura do motorista e baixa.
B5: Taxa de Conformidade do Processo de Entrega (OK) | D5: Índice de Saúde Operacional | F5: % Assinatura Motorista | H5: % Evidência | J5: % Baixado | L5: Taxa de Conformidade do Processo de Entrega (% NOK) | N5: Total Auditado
B6: =IFERROR(COUNTIFS(TRATAMENTO!B:B,"Loja Asa Norte",TRATAMENTO!K:K,"OK")/(COUNTIFS(TRATAMENTO!B:B,"Loja Asa Norte",TRATAMENTO!K:K,"OK")+COUNTIFS(TRATAMENTO!B:B,"Loja Asa Norte",TRATAMENTO!K:K,"NOK")),0) -> 0 | C6: 0 | D6: =IFERROR(SUMIFS(TRATAMENTO!V5:V500,TRATAMENTO!B5:B500,"Loja Asa Norte",TRATAMENTO!V5:V500,">0")/COUNTIFS(TRATAMENTO!B5:B500,"Loja Asa Norte",TRATAMENTO!V5:V500,">0"),0) -> 0.3 | E6: 0 | F6: =IFERROR(COUNTIFS(CONTROLE_DIARIO!B6:B500,"Loja Asa Norte",CONTROLE_DIARIO!F6:F500,"SIM")/(COUNTIFS(CONTROLE_DIARIO!B6:B500,"Loja Asa Norte",CONTROLE_DIARIO!F6:F500,"SIM")+COUNTIFS(CONTROLE_DIARIO!B6:B500,"Loja Asa Norte",CONTROLE_DIARIO!F6:F500,"NÃO")),0) -> 0 | G6: 0 | H6: =IFERROR(COUNTIFS(CONTROLE_DIARIO!B6:B500,"Loja Asa Norte",CONTROLE_DIARIO!J6:J500,"SIM")/(COUNTIFS(CONTROLE_DIARIO!B6:B500,"Loja Asa Norte",CONTROLE_DIARIO!J6:J500,"SIM")+COUNTIFS(CONTROLE_DIARIO!B6:B500,"Loja Asa Norte",CONTROLE_DIARIO!J6:J500,"NÃO")),0) -> 0 | I6: 0 | J6: =IFERROR(COUNTIFS(CONTROLE_DIARIO!B6:B500,"Loja Asa Norte",CONTROLE_DIARIO!I6:I500,"SIM")/(COUNTIFS(CONTROLE_DIARIO!B6:B500,"Loja Asa Norte",CONTROLE_DIARIO!I6:I500,"SIM")+COUNTIFS(CONTROLE_DIARIO!B6:B500,"Loja Asa Norte",CONTROLE_DIARIO!I6:I500,"NÃO")),0) -> 1 | K6: 0 | L6: =IFERROR(COUNTIFS(TRATAMENTO!B:B,"Loja Asa Norte",TRATAMENTO!K:K,"NOK")/(COUNTIFS(TRATAMENTO!B:B,"Loja Asa Norte",TRATAMENTO!K:K,"OK")+COUNTIFS(TRATAMENTO!B:B,"Loja Asa Norte",TRATAMENTO!K:K,"NOK")),0) -> 1 | M6: 0 | N6: =COUNTIF(CONTROLE_DIARIO!B:B,"Loja Asa Norte") -> 33 | O6: 0
B7: 0 | C7: 0 | D7: 0.3 | E7: 0 | F7: 0 | G7: 0 | H7: 0 | I7: 0 | J7: 1 | K7: 0 | L7: 1 | M7: 0 | N7: 21 | O7: 0
B9: Meta: ≥95% OK | Atenção: 85% a 94,9% | Crítico: abaixo de 85%
B11: EVOLUÇÃO MENSAL | H11: FALHAS IDENTIFICADAS | L11: PEDIDOS 100% OK (SEM NENHUMA FALHA)
B12: Mês | C12: Total | D12: OK | E12: NOK | F12: TCPE | H12: Erro | I12: Qtde | J12: % | L12: Status | M12: Qtde | N12: %
B13: 46113 | C13: =COUNTIFS(TRATAMENTO!B:B,"Loja Asa Norte",TRATAMENTO!A:A,">="&B13,TRATAMENTO!A:A,"<"&EDATE(B13,1)) -> 0 | D13: =COUNTIFS(TRATAMENTO!B:B,"Loja Asa Norte",TRATAMENTO!A:A,">="&B13,TRATAMENTO!A:A,"<"&EDATE(B13,1),TRATAMENTO!K:K,"OK") -> 0 | E13: =COUNTIFS(TRATAMENTO!B:B,"Loja Asa Norte",TRATAMENTO!A:A,">="&B13,TRATAMENTO!A:A,"<"&EDATE(B13,1),TRATAMENTO!K:K,"NOK") -> 0 | F13: =IFERROR(D13/C13,0) -> 0 | H13: =AUXILIAR!I3 -> Sem assinatura | I13: =COUNTIFS(TRATAMENTO!B:B,"Loja Asa Norte",TRATAMENTO!R:R,H13) -> 0 | J13: =IFERROR(I13/SUM($I$13:$I$21),0) -> 0 | L13: OK | M13: =COUNTIFS(TRATAMENTO!B:B,"Loja Asa Norte",TRATAMENTO!K:K,"OK") -> 0 | N13: =IFERROR(M13/(M13+M14),0) -> 0
B14: 46143 | C14: =COUNTIFS(TRATAMENTO!B:B,"Loja Asa Norte",TRATAMENTO!A:A,">="&B14,TRATAMENTO!A:A,"<"&EDATE(B14,1)) -> 33 | D14: =COUNTIFS(TRATAMENTO!B:B,"Loja Asa Norte",TRATAMENTO!A:A,">="&B14,TRATAMENTO!A:A,"<"&EDATE(B14,1),TRATAMENTO!K:K,"OK") -> 0 | E14: =COUNTIFS(TRATAMENTO!B:B,"Loja Asa Norte",TRATAMENTO!A:A,">="&B14,TRATAMENTO!A:A,"<"&EDATE(B14,1),TRATAMENTO!K:K,"NOK") -> 33 | F14: =IFERROR(D14/C14,0) -> 0 | H14: =AUXILIAR!I4 -> Sem nenhuma foto | I14: =COUNTIFS(TRATAMENTO!B:B,"Loja Asa Norte",TRATAMENTO!L:L,H14) -> 0 | J14: =IFERROR(I14/SUM($I$13:$I$21),0) -> 0 | L14: NOK | M14: =COUNTIFS(TRATAMENTO!B:B,"Loja Asa Norte",TRATAMENTO!K:K,"NOK") -> 33 | N14: =IFERROR(M14/(M13+M14),0) -> 1
B15: 46174 | C15: =COUNTIFS(TRATAMENTO!B:B,"Loja Asa Norte",TRATAMENTO!A:A,">="&B15,TRATAMENTO!A:A,"<"&EDATE(B15,1)) -> 0 | D15: =COUNTIFS(TRATAMENTO!B:B,"Loja Asa Norte",TRATAMENTO!A:A,">="&B15,TRATAMENTO!A:A,"<"&EDATE(B15,1),TRATAMENTO!K:K,"OK") -> 0 | E15: =COUNTIFS(TRATAMENTO!B:B,"Loja Asa Norte",TRATAMENTO!A:A,">="&B15,TRATAMENTO!A:A,"<"&EDATE(B15,1),TRATAMENTO!K:K,"NOK") -> 0 | F15: =IFERROR(D15/C15,0) -> 0 | H15: =AUXILIAR!I5 -> Sem foto fachada | I15: =COUNTIFS(TRATAMENTO!B:B,"Loja Asa Norte",TRATAMENTO!L:L,H15) -> 0 | J15: =IFERROR(I15/SUM($I$13:$I$21),0) -> 0
B16: 46204 | C16: =COUNTIFS(TRATAMENTO!B:B,"Loja Asa Norte",TRATAMENTO!A:A,">="&B16,TRATAMENTO!A:A,"<"&EDATE(B16,1)) -> 0 | D16: =COUNTIFS(TRATAMENTO!B:B,"Loja Asa Norte",TRATAMENTO!A:A,">="&B16,TRATAMENTO!A:A,"<"&EDATE(B16,1),TRATAMENTO!K:K,"OK") -> 0 | E16: =COUNTIFS(TRATAMENTO!B:B,"Loja Asa Norte",TRATAMENTO!A:A,">="&B16,TRATAMENTO!A:A,"<"&EDATE(B16,1),TRATAMENTO!K:K,"NOK") -> 0 | F16: =IFERROR(D16/C16,0) -> 0 | H16: =AUXILIAR!I6 -> Sem foto produtos | I16: =COUNTIFS(TRATAMENTO!B:B,"Loja Asa Norte",TRATAMENTO!L:L,H16) -> 0 | J16: =IFERROR(I16/SUM($I$13:$I$21),0) -> 0 | L16: STATUS SANTRI
B17: 46235 | C17: =COUNTIFS(TRATAMENTO!B:B,"Loja Asa Norte",TRATAMENTO!A:A,">="&B17,TRATAMENTO!A:A,"<"&EDATE(B17,1)) -> 0 | D17: =COUNTIFS(TRATAMENTO!B:B,"Loja Asa Norte",TRATAMENTO!A:A,">="&B17,TRATAMENTO!A:A,"<"&EDATE(B17,1),TRATAMENTO!K:K,"OK") -> 0 | E17: =COUNTIFS(TRATAMENTO!B:B,"Loja Asa Norte",TRATAMENTO!A:A,">="&B17,TRATAMENTO!A:A,"<"&EDATE(B17,1),TRATAMENTO!K:K,"NOK") -> 0 | F17: =IFERROR(D17/C17,0) -> 0 | H17: =AUXILIAR!I7 -> Sem fotos e assinatura | I17: =COUNTIFS(TRATAMENTO!B:B,"Loja Asa Norte",TRATAMENTO!R:R,H17) -> 0 | J17: =IFERROR(I17/SUM($I$13:$I$21),0) -> 0 | L17: Status | M17: Qtde
B18: 46266 | C18: =COUNTIFS(TRATAMENTO!B:B,"Loja Asa Norte",TRATAMENTO!A:A,">="&B18,TRATAMENTO!A:A,"<"&EDATE(B18,1)) -> 0 | D18: =COUNTIFS(TRATAMENTO!B:B,"Loja Asa Norte",TRATAMENTO!A:A,">="&B18,TRATAMENTO!A:A,"<"&EDATE(B18,1),TRATAMENTO!K:K,"OK") -> 0 | E18: =COUNTIFS(TRATAMENTO!B:B,"Loja Asa Norte",TRATAMENTO!A:A,">="&B18,TRATAMENTO!A:A,"<"&EDATE(B18,1),TRATAMENTO!K:K,"NOK") -> 0 | F18: =IFERROR(D18/C18,0) -> 0 | H18: =AUXILIAR!I8 -> Não conferido | I18: =COUNTIFS(TRATAMENTO!B:B,"Loja Asa Norte",TRATAMENTO!R:R,H18) -> 0 | J18: =IFERROR(I18/SUM($I$13:$I$21),0) -> 0 | L18: =AUXILIAR!G2 -> Entrega Total | M18: =COUNTIFS(CONTROLE_DIARIO!B:B,"Loja Asa Norte",CONTROLE_DIARIO!E:E,L18) -> 24
B19: 46296 | C19: =COUNTIFS(TRATAMENTO!B:B,"Loja Asa Norte",TRATAMENTO!A:A,">="&B19,TRATAMENTO!A:A,"<"&EDATE(B19,1)) -> 0 | D19: =COUNTIFS(TRATAMENTO!B:B,"Loja Asa Norte",TRATAMENTO!A:A,">="&B19,TRATAMENTO!A:A,"<"&EDATE(B19,1),TRATAMENTO!K:K,"OK") -> 0 | E19: =COUNTIFS(TRATAMENTO!B:B,"Loja Asa Norte",TRATAMENTO!A:A,">="&B19,TRATAMENTO!A:A,"<"&EDATE(B19,1),TRATAMENTO!K:K,"NOK") -> 0 | F19: =IFERROR(D19/C19,0) -> 0 | H19: =AUXILIAR!I9 -> Não baixado | I19: =COUNTIFS(TRATAMENTO!B:B,"Loja Asa Norte",TRATAMENTO!R:R,H19) -> 0 | J19: =IFERROR(I19/SUM($I$13:$I$21),0) -> 0 | L19: =AUXILIAR!G3 -> Retorno Total | M19: =COUNTIFS(CONTROLE_DIARIO!B:B,"Loja Asa Norte",CONTROLE_DIARIO!E:E,L19) -> 0
B20: 46327 | C20: =COUNTIFS(TRATAMENTO!B:B,"Loja Asa Norte",TRATAMENTO!A:A,">="&B20,TRATAMENTO!A:A,"<"&EDATE(B20,1)) -> 0 | D20: =COUNTIFS(TRATAMENTO!B:B,"Loja Asa Norte",TRATAMENTO!A:A,">="&B20,TRATAMENTO!A:A,"<"&EDATE(B20,1),TRATAMENTO!K:K,"OK") -> 0 | E20: =COUNTIFS(TRATAMENTO!B:B,"Loja Asa Norte",TRATAMENTO!A:A,">="&B20,TRATAMENTO!A:A,"<"&EDATE(B20,1),TRATAMENTO!K:K,"NOK") -> 0 | F20: =IFERROR(D20/C20,0) -> 0 | H20: Fora APP | I20: =COUNTIFS(TRATAMENTO!B:B,"Loja Asa Norte",TRATAMENTO!R:R,H20) -> 24 | J20: =IFERROR(I20/SUM($I$13:$I$21),0) -> 0.72727273 | L20: =AUXILIAR!G4 -> Entrega Parcial | M20: =COUNTIFS(CONTROLE_DIARIO!B:B,"Loja Asa Norte",CONTROLE_DIARIO!E:E,L20) -> 0
B21: 46357 | C21: =COUNTIFS(TRATAMENTO!B:B,"Loja Asa Norte",TRATAMENTO!A:A,">="&B21,TRATAMENTO!A:A,"<"&EDATE(B21,1)) -> 0 | D21: =COUNTIFS(TRATAMENTO!B:B,"Loja Asa Norte",TRATAMENTO!A:A,">="&B21,TRATAMENTO!A:A,"<"&EDATE(B21,1),TRATAMENTO!K:K,"OK") -> 0 | E21: =COUNTIFS(TRATAMENTO!B:B,"Loja Asa Norte",TRATAMENTO!A:A,">="&B21,TRATAMENTO!A:A,"<"&EDATE(B21,1),TRATAMENTO!K:K,"NOK") -> 0 | F21: =IFERROR(D21/C21,0) -> 0 | H21: =AUXILIAR!I10 -> Manifesto cancelado | I21: =COUNTIFS(TRATAMENTO!B:B,"Loja Asa Norte",TRATAMENTO!R:R,H21) -> 9 | J21: =IFERROR(I21/SUM($I$13:$I$21),0) -> 0.27272727 | L21: =AUXILIAR!G5 -> Aberto | M21: =COUNTIFS(CONTROLE_DIARIO!B:B,"Loja Asa Norte",CONTROLE_DIARIO!E:E,L21) -> 0
H22: =AUXILIAR!I11 -> Outro | I22: =COUNTIFS(TRATAMENTO!B:B,"Loja Asa Norte",TRATAMENTO!R:R,H22) -> 0 | J22: =IFERROR(I22/SUM($I$13:$I$21),0) -> 0 | L22: =AUXILIAR!G6 -> Devolução Avaria | M22: =COUNTIFS(CONTROLE_DIARIO!B:B,"Loja Asa Norte",CONTROLE_DIARIO!E:E,L22) -> 0
B23: RANKING POR MOTORISTA | L23: =AUXILIAR!G7 -> Cancelado | M23: =COUNTIFS(CONTROLE_DIARIO!B:B,"Loja Asa Norte",CONTROLE_DIARIO!E:E,L23) -> 9
B24: Motorista | C24: Auditorias | D24: OK | E24: NOK | F24: TCPE | R24: Legenda:
B25: =AUXILIAR!E4 -> J. Alessandro | C25: =COUNTIF(TRATAMENTO!B:B,"Loja Asa Norte") -> 33 | D25: =COUNTIFS(TRATAMENTO!B:B,"Loja Asa Norte",TRATAMENTO!K:K,"OK") -> 0 | E25: =COUNTIFS(TRATAMENTO!B:B,"Loja Asa Norte",TRATAMENTO!K:K,"NOK") -> 33 | F25: =IFERROR(D25/C25,0) -> 0 | R25: *TCPE = Taxa de Conformidade do Processo de Entrega

Sheet DASHBOARD VAL
B2: DASHBOARD VALPARAISO — MANIFESTO ELETRÔNICO SANTRI | Q2: GRÁFICOS DASHBOARD — MANIFESTO ELETRÔNICO SANTRI
B4: Visão executiva + operacional: lojas, motoristas, evidências, assinatura do motorista e baixa.
B5: Taxa de Conformidade do Processo de Entrega (OK) | D5: Índice de Saúde Operacional | F5: % Assinatura Motorista | H5: % Evidência | J5: % Baixado | L5: Taxa de Conformidade do Processo de Entrega (% NOK) | N5: Total Auditado
B6: =IFERROR(COUNTIFS(TRATAMENTO!B:B,"Loja Valparaiso",TRATAMENTO!K:K,"OK")/(COUNTIFS(TRATAMENTO!B:B,"Loja Valparaiso",TRATAMENTO!K:K,"OK")+COUNTIFS(TRATAMENTO!B:B,"Loja Valparaiso",TRATAMENTO!K:K,"NOK")),0) -> 0.75609756 | C6: 0 | D6: =IFERROR(SUMIFS(TRATAMENTO!V5:V500,TRATAMENTO!B5:B500,"Loja Valparaiso",TRATAMENTO!V5:V500,">0")/COUNTIFS(TRATAMENTO!B5:B500,"Loja Valparaiso",TRATAMENTO!V5:V500,">0"),0) -> 0.85641026 | E6: 0 | F6: =IFERROR(COUNTIFS(CONTROLE_DIARIO!B6:B500,"Loja Valparaiso",CONTROLE_DIARIO!F6:F500,"SIM")/(COUNTIFS(CONTROLE_DIARIO!B6:B500,"Loja Valparaiso",CONTROLE_DIARIO!F6:F500,"SIM")+COUNTIFS(CONTROLE_DIARIO!B6:B500,"Loja Valparaiso",CONTROLE_DIARIO!F6:F500,"NÃO")),0) -> 0.79487179 | G6: 0 | H6: =IFERROR(COUNTIFS(CONTROLE_DIARIO!B6:B500,"Loja Valparaiso",CONTROLE_DIARIO!J6:J500,"SIM")/(COUNTIFS(CONTROLE_DIARIO!B6:B500,"Loja Valparaiso",CONTROLE_DIARIO!J6:J500,"SIM")+COUNTIFS(CONTROLE_DIARIO!B6:B500,"Loja Valparaiso",CONTROLE_DIARIO!J6:J500,"NÃO")),0) -> 0.79487179 | I6: 0 | J6: =IFERROR(COUNTIFS(CONTROLE_DIARIO!B6:B500,"Loja Valparaiso",CONTROLE_DIARIO!I6:I500,"SIM")/(COUNTIFS(CONTROLE_DIARIO!B6:B500,"Loja Valparaiso",CONTROLE_DIARIO!I6:I500,"SIM")+COUNTIFS(CONTROLE_DIARIO!B6:B500,"Loja Valparaiso",CONTROLE_DIARIO!I6:I500,"NÃO")),0) -> 1 | K6: 0 | L6: =IFERROR(COUNTIFS(TRATAMENTO!B:B,"Loja Valparaiso",TRATAMENTO!K:K,"NOK")/(COUNTIFS(TRATAMENTO!B:B,"Loja Valparaiso",TRATAMENTO!K:K,"OK")+COUNTIFS(TRATAMENTO!B:B,"Loja Valparaiso",TRATAMENTO!K:K,"NOK")),0) -> 0.24390244 | M6: 0 | N6: =COUNTIF(CONTROLE_DIARIO!B:B,"Loja Valparaiso") -> 41 | O6: 0
B7: 0.75609756 | C7: 0 | D7: 0.85641026 | E7: 0 | F7: 0.79487179 | G7: 0 | H7: 0.79487179 | I7: 0 | J7: 1 | K7: 0 | L7: 0.24390244 | M7: 0 | N7: 41 | O7: 0
B9: Meta: ≥95% OK | Atenção: 85% a 94,9% | Crítico: abaixo de 85%
B11: EVOLUÇÃO MENSAL | H11: FALHAS IDENTIFICADAS | L11: PEDIDOS 100% OK (SEM NENHUMA FALHA)
B12: Mês | C12: Total | D12: OK | E12: NOK | F12: TCPE | H12: Erro | I12: Qtde | J12: % | L12: Status | M12: Qtde | N12: %
B13: 46113 | C13: =COUNTIFS(TRATAMENTO!B:B,"Loja Valparaiso",TRATAMENTO!A:A,">="&B13,TRATAMENTO!A:A,"<"&EDATE(B13,1)) -> 0 | D13: =COUNTIFS(TRATAMENTO!B:B,"Loja Valparaiso",TRATAMENTO!A:A,">="&B13,TRATAMENTO!A:A,"<"&EDATE(B13,1),TRATAMENTO!K:K,"OK") -> 0 | E13: =COUNTIFS(TRATAMENTO!B:B,"Loja Valparaiso",TRATAMENTO!A:A,">="&B13,TRATAMENTO!A:A,"<"&EDATE(B13,1),TRATAMENTO!K:K,"NOK") -> 0 | F13: =IFERROR(D13/C13,0) -> 0 | H13: =AUXILIAR!I3 -> Sem assinatura | I13: =COUNTIFS(TRATAMENTO!B:B,"Loja Valparaiso",TRATAMENTO!R:R,H13) -> 0 | J13: =IFERROR(I13/SUM($I$13:$I$21),0) -> 0 | L13: OK | M13: =COUNTIFS(TRATAMENTO!B:B,"Loja Valparaiso",TRATAMENTO!K:K,"OK") -> 31 | N13: =IFERROR(M13/(M13+M14),0) -> 0.75609756
B14: 46143 | C14: =COUNTIFS(TRATAMENTO!B:B,"Loja Valparaiso",TRATAMENTO!A:A,">="&B14,TRATAMENTO!A:A,"<"&EDATE(B14,1)) -> 41 | D14: =COUNTIFS(TRATAMENTO!B:B,"Loja Valparaiso",TRATAMENTO!A:A,">="&B14,TRATAMENTO!A:A,"<"&EDATE(B14,1),TRATAMENTO!K:K,"OK") -> 31 | E14: =COUNTIFS(TRATAMENTO!B:B,"Loja Valparaiso",TRATAMENTO!A:A,">="&B14,TRATAMENTO!A:A,"<"&EDATE(B14,1),TRATAMENTO!K:K,"NOK") -> 10 | F14: =IFERROR(D14/C14,0) -> 0.75609756 | H14: =AUXILIAR!I4 -> Sem nenhuma foto | I14: =COUNTIFS(TRATAMENTO!B:B,"Loja Valparaiso",TRATAMENTO!L:L,H14) -> 0 | J14: =IFERROR(I14/SUM($I$13:$I$21),0) -> 0 | L14: NOK | M14: =COUNTIFS(TRATAMENTO!B:B,"Loja Valparaiso",TRATAMENTO!K:K,"NOK") -> 10 | N14: =IFERROR(M14/(M13+M14),0) -> 0.24390244
B15: 46174 | C15: =COUNTIFS(TRATAMENTO!B:B,"Loja Valparaiso",TRATAMENTO!A:A,">="&B15,TRATAMENTO!A:A,"<"&EDATE(B15,1)) -> 0 | D15: =COUNTIFS(TRATAMENTO!B:B,"Loja Valparaiso",TRATAMENTO!A:A,">="&B15,TRATAMENTO!A:A,"<"&EDATE(B15,1),TRATAMENTO!K:K,"OK") -> 0 | E15: =COUNTIFS(TRATAMENTO!B:B,"Loja Valparaiso",TRATAMENTO!A:A,">="&B15,TRATAMENTO!A:A,"<"&EDATE(B15,1),TRATAMENTO!K:K,"NOK") -> 0 | F15: =IFERROR(D15/C15,0) -> 0 | H15: =AUXILIAR!I5 -> Sem foto fachada | I15: =COUNTIFS(TRATAMENTO!B:B,"Loja Valparaiso",TRATAMENTO!L:L,H15) -> 31 | J15: =IFERROR(I15/SUM($I$13:$I$21),0) -> 0.75609756
B16: 46204 | C16: =COUNTIFS(TRATAMENTO!B:B,"Loja Valparaiso",TRATAMENTO!A:A,">="&B16,TRATAMENTO!A:A,"<"&EDATE(B16,1)) -> 0 | D16: =COUNTIFS(TRATAMENTO!B:B,"Loja Valparaiso",TRATAMENTO!A:A,">="&B16,TRATAMENTO!A:A,"<"&EDATE(B16,1),TRATAMENTO!K:K,"OK") -> 0 | E16: =COUNTIFS(TRATAMENTO!B:B,"Loja Valparaiso",TRATAMENTO!A:A,">="&B16,TRATAMENTO!A:A,"<"&EDATE(B16,1),TRATAMENTO!K:K,"NOK") -> 0 | F16: =IFERROR(D16/C16,0) -> 0 | H16: =AUXILIAR!I6 -> Sem foto produtos | I16: =COUNTIFS(TRATAMENTO!B:B,"Loja Valparaiso",TRATAMENTO!L:L,H16) -> 0 | J16: =IFERROR(I16/SUM($I$13:$I$21),0) -> 0 | L16: STATUS SANTRI
B17: 46235 | C17: =COUNTIFS(TRATAMENTO!B:B,"Loja Valparaiso",TRATAMENTO!A:A,">="&B17,TRATAMENTO!A:A,"<"&EDATE(B17,1)) -> 0 | D17: =COUNTIFS(TRATAMENTO!B:B,"Loja Valparaiso",TRATAMENTO!A:A,">="&B17,TRATAMENTO!A:A,"<"&EDATE(B17,1),TRATAMENTO!K:K,"OK") -> 0 | E17: =COUNTIFS(TRATAMENTO!B:B,"Loja Valparaiso",TRATAMENTO!A:A,">="&B17,TRATAMENTO!A:A,"<"&EDATE(B17,1),TRATAMENTO!K:K,"NOK") -> 0 | F17: =IFERROR(D17/C17,0) -> 0 | H17: =AUXILIAR!I7 -> Sem fotos e assinatura | I17: =COUNTIFS(TRATAMENTO!B:B,"Loja Valparaiso",TRATAMENTO!R:R,H17) -> 0 | J17: =IFERROR(I17/SUM($I$13:$I$21),0) -> 0 | L17: Status | M17: Qtde
B18: 46266 | C18: =COUNTIFS(TRATAMENTO!B:B,"Loja Valparaiso",TRATAMENTO!A:A,">="&B18,TRATAMENTO!A:A,"<"&EDATE(B18,1)) -> 0 | D18: =COUNTIFS(TRATAMENTO!B:B,"Loja Valparaiso",TRATAMENTO!A:A,">="&B18,TRATAMENTO!A:A,"<"&EDATE(B18,1),TRATAMENTO!K:K,"OK") -> 0 | E18: =COUNTIFS(TRATAMENTO!B:B,"Loja Valparaiso",TRATAMENTO!A:A,">="&B18,TRATAMENTO!A:A,"<"&EDATE(B18,1),TRATAMENTO!K:K,"NOK") -> 0 | F18: =IFERROR(D18/C18,0) -> 0 | H18: =AUXILIAR!I8 -> Não conferido | I18: =COUNTIFS(TRATAMENTO!B:B,"Loja Valparaiso",TRATAMENTO!R:R,H18) -> 0 | J18: =IFERROR(I18/SUM($I$13:$I$21),0) -> 0 | L18: =AUXILIAR!G2 -> Entrega Total | M18: =COUNTIFS(CONTROLE_DIARIO!B:B,"Loja Valparaiso",CONTROLE_DIARIO!E:E,L18) -> 39
B19: 46296 | C19: =COUNTIFS(TRATAMENTO!B:B,"Loja Valparaiso",TRATAMENTO!A:A,">="&B19,TRATAMENTO!A:A,"<"&EDATE(B19,1)) -> 0 | D19: =COUNTIFS(TRATAMENTO!B:B,"Loja Valparaiso",TRATAMENTO!A:A,">="&B19,TRATAMENTO!A:A,"<"&EDATE(B19,1),TRATAMENTO!K:K,"OK") -> 0 | E19: =COUNTIFS(TRATAMENTO!B:B,"Loja Valparaiso",TRATAMENTO!A:A,">="&B19,TRATAMENTO!A:A,"<"&EDATE(B19,1),TRATAMENTO!K:K,"NOK") -> 0 | F19: =IFERROR(D19/C19,0) -> 0 | H19: =AUXILIAR!I9 -> Não baixado | I19: =COUNTIFS(TRATAMENTO!B:B,"Loja Valparaiso",TRATAMENTO!R:R,H19) -> 0 | J19: =IFERROR(I19/SUM($I$13:$I$21),0) -> 0 | L19: =AUXILIAR!G3 -> Retorno Total | M19: =COUNTIFS(CONTROLE_DIARIO!B:B,"Loja Valparaiso",CONTROLE_DIARIO!E:E,L19) -> 0
B20: 46327 | C20: =COUNTIFS(TRATAMENTO!B:B,"Loja Valparaiso",TRATAMENTO!A:A,">="&B20,TRATAMENTO!A:A,"<"&EDATE(B20,1)) -> 0 | D20: =COUNTIFS(TRATAMENTO!B:B,"Loja Valparaiso",TRATAMENTO!A:A,">="&B20,TRATAMENTO!A:A,"<"&EDATE(B20,1),TRATAMENTO!K:K,"OK") -> 0 | E20: =COUNTIFS(TRATAMENTO!B:B,"Loja Valparaiso",TRATAMENTO!A:A,">="&B20,TRATAMENTO!A:A,"<"&EDATE(B20,1),TRATAMENTO!K:K,"NOK") -> 0 | F20: =IFERROR(D20/C20,0) -> 0 | H20: Fora APP | I20: =COUNTIFS(TRATAMENTO!B:B,"Loja Valparaiso",TRATAMENTO!R:R,H20) -> 8 | J20: =IFERROR(I20/SUM($I$13:$I$21),0) -> 0.19512195 | L20: =AUXILIAR!G4 -> Entrega Parcial | M20: =COUNTIFS(CONTROLE_DIARIO!B:B,"Loja Valparaiso",CONTROLE_DIARIO!E:E,L20) -> 0
B21: 46357 | C21: =COUNTIFS(TRATAMENTO!B:B,"Loja Valparaiso",TRATAMENTO!A:A,">="&B21,TRATAMENTO!A:A,"<"&EDATE(B21,1)) -> 0 | D21: =COUNTIFS(TRATAMENTO!B:B,"Loja Valparaiso",TRATAMENTO!A:A,">="&B21,TRATAMENTO!A:A,"<"&EDATE(B21,1),TRATAMENTO!K:K,"OK") -> 0 | E21: =COUNTIFS(TRATAMENTO!B:B,"Loja Valparaiso",TRATAMENTO!A:A,">="&B21,TRATAMENTO!A:A,"<"&EDATE(B21,1),TRATAMENTO!K:K,"NOK") -> 0 | F21: =IFERROR(D21/C21,0) -> 0 | H21: =AUXILIAR!I10 -> Manifesto cancelado | I21: =COUNTIFS(TRATAMENTO!B:B,"Loja Valparaiso",TRATAMENTO!R:R,H21) -> 2 | J21: =IFERROR(I21/SUM($I$13:$I$21),0) -> 0.048780488 | L21: =AUXILIAR!G5 -> Aberto | M21: =COUNTIFS(CONTROLE_DIARIO!B:B,"Loja Valparaiso",CONTROLE_DIARIO!E:E,L21) -> 0
H22: =AUXILIAR!I11 -> Outro | I22: =COUNTIFS(TRATAMENTO!B:B,"Loja Valparaiso",TRATAMENTO!R:R,H22) -> 0 | J22: =IFERROR(I22/SUM($I$13:$I$21),0) -> 0 | L22: =AUXILIAR!G6 -> Devolução Avaria | M22: =COUNTIFS(CONTROLE_DIARIO!B:B,"Loja Valparaiso",CONTROLE_DIARIO!E:E,L22) -> 0
B23: RANKING POR MOTORISTA | L23: =AUXILIAR!G7 -> Cancelado | M23: =COUNTIFS(CONTROLE_DIARIO!B:B,"Loja Valparaiso",CONTROLE_DIARIO!E:E,L23) -> 2
B24: Motorista | C24: Auditorias | D24: OK | E24: NOK | F24: TCPE | R24: Legenda:
B25: =AUXILIAR!E5 -> Wederson C. | C25: =COUNTIFS(TRATAMENTO!B:B,"Loja Valparaiso",TRATAMENTO!D:D,B25) -> 40 | D25: =COUNTIFS(TRATAMENTO!B:B,"Loja Valparaiso",TRATAMENTO!D:D,B25,TRATAMENTO!K:K,"OK") -> 31 | E25: =COUNTIFS(TRATAMENTO!B:B,"Loja Valparaiso",TRATAMENTO!D:D,B25,TRATAMENTO!K:K,"NOK") -> 9 | F25: =IFERROR(D25/C25,0) -> 0.775 | R25: *TCPE = Taxa de Conformidade do Processo de Entrega

Sheet GERENTES
B2: PAINEL PARA ESCALAR AOS GERENTES
B4: Use esta aba quando os gerentes começarem a auditar: mede volume, qualidade, falhas e atuação.
B6: Gerente | C6: Auditorias | D6: OK | E6: NOK | F6: TCPE | G6: Não conferido | H6: Não baixado | I6: Sem foto | J6: Sem assinatura | K6: Sem foto e assinatura | L6: Manifestos cancelados | M6: Fora APP | N6: Ação Recomendada
B7: =AUXILIAR!K2 -> Cinthya | C7: =COUNTIF(TRATAMENTO!O:O,B7) -> 44 | D7: =COUNTIFS(TRATAMENTO!O:O,B7,TRATAMENTO!K:K,"OK") -> 31 | E7: =COUNTIFS(TRATAMENTO!O:O,B7,TRATAMENTO!K:K,"NOK") -> 13 | F7: =IFERROR(D7/C7,0) -> 0.70454545 | G7: =COUNTIFS(TRATAMENTO!O:O,B7,TRATAMENTO!R:R,"Não conferido") -> 0 | H7: =COUNTIFS(TRATAMENTO!O:O,B7,TRATAMENTO!R:R,"Não baixado") -> 0 | I7: =COUNTIFS(TRATAMENTO!O:O,B7,TRATAMENTO!R:R,"Sem foto") -> 1 | J7: =COUNTIFS(TRATAMENTO!O:O,B7,TRATAMENTO!R:R,"Sem assinatura") -> 0 | K7: =COUNTIFS(TRATAMENTO!O:O,B7,TRATAMENTO!R:R,"Sem foto e assinatura") -> 0 | L7: =COUNTIFS(TRATAMENTO!O:O,B7,TRATAMENTO!R:R,"Manifesto cancelado") -> 1 | M7: =COUNTIFS(TRATAMENTO!O:O,B7,TRATAMENTO!R:R,"FORA APP") -> 3 | N7: =IF(F7<0.85,"Plano de ação imediato",IF(F7<0.95,"Acompanhar diariamente","Manter padrão")) -> Plano de ação imediato
B8: =AUXILIAR!K3 -> Danilo | C8: =COUNTIF(TRATAMENTO!O:O,B8) -> 38 | D8: =COUNTIFS(TRATAMENTO!O:O,B8,TRATAMENTO!K:K,"OK") -> 25 | E8: =COUNTIFS(TRATAMENTO!O:O,B8,TRATAMENTO!K:K,"NOK") -> 13 | F8: =IFERROR(D8/C8,0) -> 0.65789474 | G8: =COUNTIFS(TRATAMENTO!O:O,B8,TRATAMENTO!R:R,"Não conferido") -> 0 | H8: =COUNTIFS(TRATAMENTO!O:O,B8,TRATAMENTO!R:R,"Não baixado") -> 0 | I8: =COUNTIFS(TRATAMENTO!O:O,B8,TRATAMENTO!R:R,"Sem foto") -> 0 | J8: =COUNTIFS(TRATAMENTO!O:O,B8,TRATAMENTO!R:R,"Sem assinatura") -> 2 | K8: =COUNTIFS(TRATAMENTO!O:O,B8,TRATAMENTO!R:R,"Sem foto e assinatura") -> 0 | L8: =COUNTIFS(TRATAMENTO!O:O,B8,TRATAMENTO!R:R,"Manifesto cancelado") -> 1 | M8: =COUNTIFS(TRATAMENTO!O:O,B8,TRATAMENTO!R:R,"FORA APP") -> 2 | N8: =IF(F8<0.85,"Plano de ação imediato",IF(F8<0.95,"Acompanhar diariamente","Manter padrão")) -> Plano de ação imediato
B9: =AUXILIAR!K4 -> Neudo | C9: =COUNTIF(TRATAMENTO!O:O,B9) -> 33 | D9: =COUNTIFS(TRATAMENTO!O:O,B9,TRATAMENTO!K:K,"OK") -> 0 | E9: =COUNTIFS(TRATAMENTO!O:O,B9,TRATAMENTO!K:K,"NOK") -> 33 | F9: =IFERROR(D9/C9,0) -> 0 | G9: =COUNTIFS(TRATAMENTO!O:O,B9,TRATAMENTO!R:R,"Não conferido") -> 0 | H9: =COUNTIFS(TRATAMENTO!O:O,B9,TRATAMENTO!R:R,"Não baixado") -> 0 | I9: =COUNTIFS(TRATAMENTO!O:O,B9,TRATAMENTO!R:R,"Sem foto") -> 0 | J9: =COUNTIFS(TRATAMENTO!O:O,B9,TRATAMENTO!R:R,"Sem assinatura") -> 0 | K9: =COUNTIFS(TRATAMENTO!O:O,B9,TRATAMENTO!R:R,"Sem foto e assinatura") -> 0 | L9: =COUNTIFS(TRATAMENTO!O:O,B9,TRATAMENTO!R:R,"Manifesto cancelado") -> 9 | M9: =COUNTIFS(TRATAMENTO!O:O,B9,TRATAMENTO!R:R,"FORA APP") -> 24 | N9: =IF(F9<0.85,"Plano de ação imediato",IF(F9<0.95,"Acompanhar diariamente","Manter padrão")) -> Plano de ação imediato
B10: =AUXILIAR!K5 -> Natália | C10: =COUNTIF(TRATAMENTO!O:O,B10) -> 3 | D10: =COUNTIFS(TRATAMENTO!O:O,B10,TRATAMENTO!K:K,"OK") -> 0 | E10: =COUNTIFS(TRATAMENTO!O:O,B10,TRATAMENTO!K:K,"NOK") -> 3 | F10: =IFERROR(D10/C10,0) -> 0 | G10: =COUNTIFS(TRATAMENTO!O:O,B10,TRATAMENTO!R:R,"Não conferido") -> 0 | H10: =COUNTIFS(TRATAMENTO!O:O,B10,TRATAMENTO!R:R,"Não baixado") -> 0 | I10: =COUNTIFS(TRATAMENTO!O:O,B10,TRATAMENTO!R:R,"Sem foto") -> 0 | J10: =COUNTIFS(TRATAMENTO!O:O,B10,TRATAMENTO!R:R,"Sem assinatura") -> 0 | K10: =COUNTIFS(TRATAMENTO!O:O,B10,TRATAMENTO!R:R,"Sem foto e assinatura") -> 0 | L10: =COUNTIFS(TRATAMENTO!O:O,B10,TRATAMENTO!R:R,"Manifesto cancelado") -> 0 | M10: =COUNTIFS(TRATAMENTO!O:O,B10,TRATAMENTO!R:R,"FORA APP") -> 3 | N10: =IF(F10<0.85,"Plano de ação imediato",IF(F10<0.95,"Acompanhar diariamente","Manter padrão")) -> Plano de ação imediato
B11: =AUXILIAR!K6 -> Luciano | C11: =COUNTIF(TRATAMENTO!O:O,B11) -> 0 | D11: =COUNTIFS(TRATAMENTO!O:O,B11,TRATAMENTO!K:K,"OK") -> 0 | E11: =COUNTIFS(TRATAMENTO!O:O,B11,TRATAMENTO!K:K,"NOK") -> 0 | F11: =IFERROR(D11/C11,0) -> 0 | G11: =COUNTIFS(TRATAMENTO!O:O,B11,TRATAMENTO!R:R,"Não conferido") -> 0 | H11: =COUNTIFS(TRATAMENTO!O:O,B11,TRATAMENTO!R:R,"Não baixado") -> 0 | I11: =COUNTIFS(TRATAMENTO!O:O,B11,TRATAMENTO!R:R,"Sem foto") -> 0 | J11: =COUNTIFS(TRATAMENTO!O:O,B11,TRATAMENTO!R:R,"Sem assinatura") -> 0 | K11: =COUNTIFS(TRATAMENTO!O:O,B11,TRATAMENTO!R:R,"Sem foto e assinatura") -> 0 | L11: =COUNTIFS(TRATAMENTO!O:O,B11,TRATAMENTO!R:R,"Manifesto cancelado") -> 0 | M11: =COUNTIFS(TRATAMENTO!O:O,B11,TRATAMENTO!R:R,"FORA APP") -> 0 | N11: =IF(F11<0.85,"Plano de ação imediato",IF(F11<0.95,"Acompanhar diariamente","Manter padrão")) -> Plano de ação imediato
B12: =AUXILIAR!K7 -> Cleonice | C12: =COUNTIF(TRATAMENTO!O:O,B12) -> 41 | D12: =COUNTIFS(TRATAMENTO!O:O,B12,TRATAMENTO!K:K,"OK") -> 31 | E12: =COUNTIFS(TRATAMENTO!O:O,B12,TRATAMENTO!K:K,"NOK") -> 10 | F12: =IFERROR(D12/C12,0) -> 0.75609756 | G12: =COUNTIFS(TRATAMENTO!O:O,B12,TRATAMENTO!R:R,"Não conferido") -> 0 | H12: =COUNTIFS(TRATAMENTO!O:O,B12,TRATAMENTO!R:R,"Não baixado") -> 0 | I12: =COUNTIFS(TRATAMENTO!O:O,B12,TRATAMENTO!R:R,"Sem foto") -> 0 | J12: =COUNTIFS(TRATAMENTO!O:O,B12,TRATAMENTO!R:R,"Sem assinatura") -> 0 | K12: =COUNTIFS(TRATAMENTO!O:O,B12,TRATAMENTO!R:R,"Sem foto e assinatura") -> 0 | L12: =COUNTIFS(TRATAMENTO!O:O,B12,TRATAMENTO!R:R,"Manifesto cancelado") -> 2 | M12: =COUNTIFS(TRATAMENTO!O:O,B12,TRATAMENTO!R:R,"FORA APP") -> 8 | N12: =IF(F12<0.85,"Plano de ação imediato",IF(F12<0.95,"Acompanhar diariamente","Manter padrão")) -> Plano de ação imediato
B13: =AUXILIAR!K8 -> Sérgio | C13: =COUNTIF(TRATAMENTO!O:O,B13) -> 0 | D13: =COUNTIFS(TRATAMENTO!O:O,B13,TRATAMENTO!K:K,"OK") -> 0 | E13: =COUNTIFS(TRATAMENTO!O:O,B13,TRATAMENTO!K:K,"NOK") -> 0 | F13: =IFERROR(D13/C13,0) -> 0 | G13: =COUNTIFS(TRATAMENTO!O:O,B13,TRATAMENTO!R:R,"Não conferido") -> 0 | H13: =COUNTIFS(TRATAMENTO!O:O,B13,TRATAMENTO!R:R,"Não baixado") -> 0 | I13: =COUNTIFS(TRATAMENTO!O:O,B13,TRATAMENTO!R:R,"Sem foto") -> 0 | J13: =COUNTIFS(TRATAMENTO!O:O,B13,TRATAMENTO!R:R,"Sem assinatura") -> 0 | K13: =COUNTIFS(TRATAMENTO!O:O,B13,TRATAMENTO!R:R,"Sem foto e assinatura") -> 0 | L13: =COUNTIFS(TRATAMENTO!O:O,B13,TRATAMENTO!R:R,"Manifesto cancelado") -> 0 | M13: =COUNTIFS(TRATAMENTO!O:O,B13,TRATAMENTO!R:R,"FORA APP") -> 0 | N13: =IF(F13<0.85,"Plano de ação imediato",IF(F13<0.95,"Acompanhar diariamente","Manter padrão")) -> Plano de ação imediato
J28: Legenda:
J29: * TCPE = Taxa de Conformidade do Processo de Entrega

Sheet CONTROLE_DIARIO
A1: CONTROLE DIÁRIO — AUDITORIA SANTRI
A3: Preenchimento rápido: validar MANIFESTOS para assinatura do motorista e ENTREGAS para foto + assinatura do cliente.
A5: Data Auditoria | B5: Loja | C5: Nº Manifesto | D5: Motorista | E5: Status SANTRI | F5: Assinatura Motorista? | G5: Foto Entrega? | H5: Assinatura Cliente? | I5: Baixado? | J5: Evidência Completa | K5: OK/NOK | L5: Erro Padrão | M5: Observação | N5: Auditado por | O5: Gerente Resp. | P5: Chave | R5: GUIA RÁPIDO
A6: 46141 | B6: Loja ADE | C6: 3895 | D6: João Lucas | E6: Entrega Total | F6: SIM | G6: SIM | H6: SIM | I6: SIM | J6: =IF(C6="","",IF(E6="Retorno Total"," ",IF(E6="Cancelado"," ",IF(AND(G6="SIM",H6="SIM"),"SIM","NÃO")))) -> SIM | K6: =IF(C6="","",IF(AND(F6="SIM",I6="SIM",J6="SIM"),"OK","NOK")) -> OK | L6: OK | N6: Qualidade | O6: =IF(B6="","",IFERROR(IF(VLOOKUP(B6,AUXILIAR!$O$2:$P$50,2,FALSE)="","CADASTRAR GERENTE",VLOOKUP(B6,AUXILIAR!$O$2:$P$50,2,FALSE)),"CADASTRAR GERENTE")) -> Danilo | P6: =IF(C6="","",TEXT(A6,"yyyymmdd")&"-"&B6&"-"&C6) -> yyyy0429-Loja ADE-3895 | R6: 1. Abra MANIFESTOS no SANTRI.
A7: 46141 | B7: Loja ADE | C7: 3896 | D7: João Lucas | E7: Entrega Total | F7: SIM | G7: SIM | H7: SIM | I7: SIM | J7: =IF(C7="","",IF(E7="Retorno Total"," ",IF(E7="Cancelado"," ",IF(AND(G7="SIM",H7="SIM"),"SIM","NÃO")))) -> SIM | K7: =IF(C7="","",IF(AND(F7="SIM",I7="SIM",J7="SIM"),"OK","NOK")) -> OK | L7: OK | N7: Qualidade | O7: =IF(B7="","",IFERROR(IF(VLOOKUP(B7,AUXILIAR!$O$2:$P$50,2,FALSE)="","CADASTRAR GERENTE",VLOOKUP(B7,AUXILIAR!$O$2:$P$50,2,FALSE)),"CADASTRAR GERENTE")) -> Danilo | P7: =IF(C7="","",TEXT(A7,"yyyymmdd")&"-"&B7&"-"&C7) -> yyyy0429-Loja ADE-3896 | R7: 2. Verifique assinatura do motorista.
A8: 46141 | B8: Loja ADE | C8: 3897 | D8: João Lucas | E8: Entrega Total | F8: SIM | G8: SIM | H8: NÃO | I8: SIM | J8: =IF(C8="","",IF(E8="Retorno Total"," ",IF(E8="Cancelado"," ",IF(AND(G8="SIM",H8="SIM"),"SIM","NÃO")))) -> NÃO | K8: =IF(C8="","",IF(AND(F8="SIM",I8="SIM",J8="SIM"),"OK","NOK")) -> NOK | L8: Sem assinatura | N8: Qualidade | O8: =IF(B8="","",IFERROR(IF(VLOOKUP(B8,AUXILIAR!$O$2:$P$50,2,FALSE)="","CADASTRAR GERENTE",VLOOKUP(B8,AUXILIAR!$O$2:$P$50,2,FALSE)),"CADASTRAR GERENTE")) -> Danilo | P8: =IF(C8="","",TEXT(A8,"yyyymmdd")&"-"&B8&"-"&C8) -> yyyy0429-Loja ADE-3897 | R8: 3. Abra ENTREGAS > Fotos.
A9: 46141 | B9: Loja ADE | C9: 3901 | D9: João Lucas | E9: Entrega Total | F9: SIM | G9: SIM | H9: SIM | I9: SIM | J9: =IF(C9="","",IF(E9="Retorno Total"," ",IF(E9="Cancelado"," ",IF(AND(G9="SIM",H9="SIM"),"SIM","NÃO")))) -> SIM | K9: =IF(C9="","",IF(AND(F9="SIM",I9="SIM",J9="SIM"),"OK","NOK")) -> OK | L9: OK | N9: Qualidade | O9: =IF(B9="","",IFERROR(IF(VLOOKUP(B9,AUXILIAR!$O$2:$P$50,2,FALSE)="","CADASTRAR GERENTE",VLOOKUP(B9,AUXILIAR!$O$2:$P$50,2,FALSE)),"CADASTRAR GERENTE")) -> Danilo | P9: =IF(C9="","",TEXT(A9,"yyyymmdd")&"-"&B9&"-"&C9) -> yyyy0429-Loja ADE-3901 | R9: 4. Valide foto e assinatura do cliente.
A10: 46149 | B10: Loja Pistão | C10: 3902 | D10: João Lucas | E10: Entrega Total | F10: SIM | G10: SIM | H10: SIM | I10: SIM | J10: =IF(C10="","",IF(E10="Retorno Total"," ",IF(E10="Cancelado"," ",IF(AND(G10="SIM",H10="SIM"),"SIM","NÃO")))) -> SIM | K10: =IF(C10="","",IF(AND(F10="SIM",I10="SIM",J10="SIM"),"OK","NOK")) -> OK | L10: OK | N10: Qualidade | O10: =IF(B10="","",IFERROR(IF(VLOOKUP(B10,AUXILIAR!$O$2:$P$50,2,FALSE)="","CADASTRAR GERENTE",VLOOKUP(B10,AUXILIAR!$O$2:$P$50,2,FALSE)),"CADASTRAR GERENTE")) -> Cinthya | P10: =IF(C10="","",TEXT(A10,"yyyymmdd")&"-"&B10&"-"&C10) -> yyyy0507-Loja Pistão-3902 | R10: 5. Marque SIM/NÃO e o dashboard atualiza.
A11: 46149 | B11: Loja Pistão | C11: 3903 | D11: João Lucas | E11: Cancelado | J11: =IF(C11="","",IF(E11="Retorno Total"," ",IF(E11="Cancelado"," ",IF(AND(G11="SIM",H11="SIM"),"SIM","NÃO")))) | K11: =IF(C11="","",IF(AND(F11="SIM",I11="SIM",J11="SIM"),"OK","NOK")) -> NOK | L11: Manifesto cancelado | N11: Qualidade | O11: =IF(B11="","",IFERROR(IF(VLOOKUP(B11,AUXILIAR!$O$2:$P$50,2,FALSE)="","CADASTRAR GERENTE",VLOOKUP(B11,AUXILIAR!$O$2:$P$50,2,FALSE)),"CADASTRAR GERENTE")) -> Cinthya | P11: =IF(C11="","",TEXT(A11,"yyyymmdd")&"-"&B11&"-"&C11) -> yyyy0507-Loja Pistão-3903
A12: 46141 | B12: Loja ADE | C12: 3904 | D12: João Lucas | E12: Entrega Total | F12: SIM | G12: SIM | H12: SIM | I12: SIM | J12: =IF(C12="","",IF(E12="Retorno Total"," ",IF(E12="Cancelado"," ",IF(AND(G12="SIM",H12="SIM"),"SIM","NÃO")))) -> SIM | K12: =IF(C12="","",IF(AND(F12="SIM",I12="SIM",J12="SIM"),"OK","NOK")) -> OK | L12: Sem foto fachada | N12: Qualidade | O12: =IF(B12="","",IFERROR(IF(VLOOKUP(B12,AUXILIAR!$O$2:$P$50,2,FALSE)="","CADASTRAR GERENTE",VLOOKUP(B12,AUXILIAR!$O$2:$P$50,2,FALSE)),"CADASTRAR GERENTE")) -> Danilo | P12: =IF(C12="","",TEXT(A12,"yyyymmdd")&"-"&B12&"-"&C12) -> yyyy0429-Loja ADE-3904
A13: 46141 | B13: Loja ADE | C13: 3905 | D13: João Lucas | E13: Entrega Total | F13: SIM | G13: SIM | H13: NÃO | I13: SIM | J13: =IF(C13="","",IF(E13="Retorno Total"," ",IF(E13="Cancelado"," ",IF(AND(G13="SIM",H13="SIM"),"SIM","NÃO")))) -> NÃO | K13: =IF(C13="","",IF(AND(F13="SIM",I13="SIM",J13="SIM"),"OK","NOK")) -> NOK | L13: Sem assinatura | N13: Qualidade | O13: =IF(B13="","",IFERROR(IF(VLOOKUP(B13,AUXILIAR!$O$2:$P$50,2,FALSE)="","CADASTRAR GERENTE",VLOOKUP(B13,AUXILIAR!$O$2:$P$50,2,FALSE)),"CADASTRAR GERENTE")) -> Danilo | P13: =IF(C13="","",TEXT(A13,"yyyymmdd")&"-"&B13&"-"&C13) -> yyyy0429-Loja ADE-3905
A14: 46141 | B14: Loja ADE | C14: 3906 | D14: João Lucas | E14: Entrega Total | F14: SIM | G14: SIM | H14: SIM | I14: SIM | J14: =IF(C14="","",IF(E14="Retorno Total"," ",IF(E14="Cancelado"," ",IF(AND(G14="SIM",H14="SIM"),"SIM","NÃO")))) -> SIM | K14: =IF(C14="","",IF(AND(F14="SIM",I14="SIM",J14="SIM"),"OK","NOK")) -> OK | L14: OK | N14: Qualidade | O14: =IF(B14="","",IFERROR(IF(VLOOKUP(B14,AUXILIAR!$O$2:$P$50,2,FALSE)="","CADASTRAR GERENTE",VLOOKUP(B14,AUXILIAR!$O$2:$P$50,2,FALSE)),"CADASTRAR GERENTE")) -> Danilo | P14: =IF(C14="","",TEXT(A14,"yyyymmdd")&"-"&B14&"-"&C14) -> yyyy0429-Loja ADE-3906
A15: 46141 | B15: Loja ADE | C15: 3907 | D15: João Lucas | E15: Entrega Total | F15: SIM | G15: SIM | H15: SIM | I15: SIM | J15: =IF(C15="","",IF(E15="Retorno Total"," ",IF(E15="Cancelado"," ",IF(AND(G15="SIM",H15="SIM"),"SIM","NÃO")))) -> SIM | K15: =IF(C15="","",IF(AND(F15="SIM",I15="SIM",J15="SIM"),"OK","NOK")) -> OK | L15: OK | N15: Qualidade | O15: =IF(B15="","",IFERROR(IF(VLOOKUP(B15,AUXILIAR!$O$2:$P$50,2,FALSE)="","CADASTRAR GERENTE",VLOOKUP(B15,AUXILIAR!$O$2:$P$50,2,FALSE)),"CADASTRAR GERENTE")) -> Danilo | P15: =IF(C15="","",TEXT(A15,"yyyymmdd")&"-"&B15&"-"&C15) -> yyyy0429-Loja ADE-3907
